test_user,123,. Error:Test failed: Expected '', got 'Hello World!'
test_user,123,. Error:[Errno 2] No such file or directory: 'challenges/123/problem.json'
test_user,123,. Error:[Errno 2] No such file or directory: 'challenges/123/problem.json'
test_user,123,. Error:[Errno 2] No such file or directory: 'challenges/123/problem.json'
test_user,[object HTMLDivElement],. Error:[Errno 2] No such file or directory: 'challenges/[object HTMLDivElement]/problem.json'
test_user,[object HTMLDivElement],. Error:[Errno 2] No such file or directory: 'challenges/[object HTMLDivElement]/problem.json'
test_user,[object HTMLDivElement],. Error:[Errno 2] No such file or directory: 'challenges/[object HTMLDivElement]/problem.json'
test_user,2,AssertionError(): expecting 8, got: . Error:
test_user,2,Test passed.. Error:
test_user,2,AssertionError(): expecting 8, got: 9. Error:
test_user,2,Test passed.. Error:
test_user,2,Test passed.. Error:
test_user,2,AssertionError(): expecting 8, got: . Error:
test_user,2,AssertionError(): expecting 8, got: 11. Error:
test_user,2,AssertionError(): expecting 8, got: 11. Error:
test_user,2,Test passed.. Error:
test_user,2.2,Test passed.. Error:
test_user,2.2,Test passed.. Error:
test_user,2.2,Test passed.. Error:
test_user,2.2,Test passed.. Error:
test_user,2.2,AssertionError(): test failed: ============================= test session starts ==============================
platform linux -- Python 3.11.4, pytest-7.3.1, pluggy-1.0.0
rootdir: /workspaces/python-challenges
plugins: anyio-4.4.0
collected 1 item

challenges/2.2/test_solution.py F                                        [100%]

=================================== FAILURES ===================================
________________________________ test_solution _________________________________

user_file = 'user_submissions/test_user/2.2.py'
capsys = <_pytest.capture.CaptureFixture object at 0x71f0ffc54790>

    def test_solution(user_file: str, capsys):
        """run the user submitted code to test it."""
        my_dir, _ = os.path.split(__file__)
        _, my_id = os.path.split(my_dir)
    
        print(f"{user_file=}")
    
        challenge_data = challenge_details(my_id)
        startting_code = challenge_data.get("startting_code", '')
        with open(user_file, "rt", encoding='utf-8') as uf:
            code_to_test = uf.read()
        #code_to_test.replace(startting_code, "test_set")
    
        exec(code_to_test)
        captured = capsys.readouterr()
        print(f"{captured=}")
>       assert captured.out == "8"
E       assert "user_file='u...ser/2.2.py'\n" == '8'
E         - 8
E         + user_file='user_submissions/test_user/2.2.py'

challenges/2.2/test_solution.py:23: AssertionError
----------------------------- Captured stdout call -----------------------------
captured=CaptureResult(out="user_file='user_submissions/test_user/2.2.py'\n", err='')
=========================== short test summary info ============================
FAILED challenges/2.2/test_solution.py::test_solution - assert "user_file='u....
============================== 1 failed in 0.17s ===============================. Error:
test_user,2.2,AssertionError(): test failed: ============================= test session starts ==============================
platform linux -- Python 3.11.4, pytest-7.3.1, pluggy-1.0.0
rootdir: /workspaces/python-challenges
plugins: anyio-4.4.0
collected 1 item

challenges/2.2/test_solution.py F                                        [100%]

=================================== FAILURES ===================================
________________________________ test_solution _________________________________

user_file = 'user_submissions/test_user/2.2.py'
capsys = <_pytest.capture.CaptureFixture object at 0x7225e485bfd0>

    def test_solution(user_file: str, capsys):
        """run the user submitted code to test it."""
        my_dir, _ = os.path.split(__file__)
        _, my_id = os.path.split(my_dir)
    
    
        challenge_data = challenge_details(my_id)
        startting_code = challenge_data.get("startting_code", '')
        with open(user_file, "rt", encoding='utf-8') as uf:
            code_to_test = uf.read()
        #code_to_test.replace(startting_code, "test_set")
    
        exec(code_to_test)
        captured = capsys.readouterr()
>       assert captured.out == "8"
E       AssertionError: assert '' == '8'
E         - 8

challenges/2.2/test_solution.py:21: AssertionError
=========================== short test summary info ============================
FAILED challenges/2.2/test_solution.py::test_solution - AssertionError: asser...
============================== 1 failed in 0.28s ===============================. Error:
test_user,2.2,AssertionError(): test failed: ============================= test session starts ==============================
platform linux -- Python 3.11.4, pytest-7.3.1, pluggy-1.0.0
rootdir: /workspaces/python-challenges
plugins: anyio-4.4.0
collected 1 item

challenges/2.2/test_solution.py F                                        [100%]

=================================== FAILURES ===================================
________________________________ test_solution _________________________________

user_file = 'user_submissions/test_user/2.2.py'
capsys = <_pytest.capture.CaptureFixture object at 0x7b9b5e73a6d0>

    def test_solution(user_file: str, capsys):
        """run the user submitted code to test it."""
        my_dir, _ = os.path.split(__file__)
        _, my_id = os.path.split(my_dir)
    
    
        challenge_data = challenge_details(my_id)
        startting_code = challenge_data.get("startting_code", '')
        with open(user_file, "rt", encoding='utf-8') as uf:
            code_to_test = uf.read()
        #code_to_test.replace(startting_code, "test_set")
    
        exec(code_to_test)
        captured = capsys.readouterr()
>       assert captured.out == "8"
E       AssertionError: assert '8\n' == '8'
E         - 8
E         + 8

challenges/2.2/test_solution.py:21: AssertionError
=========================== short test summary info ============================
FAILED challenges/2.2/test_solution.py::test_solution - AssertionError: asser...
============================== 1 failed in 0.18s ===============================. Error:
test_user,2.2,AssertionError(): test failed: ============================= test session starts ==============================
platform linux -- Python 3.11.4, pytest-7.3.1, pluggy-1.0.0
rootdir: /workspaces/python-challenges
plugins: anyio-4.4.0
collected 1 item

challenges/2.2/test_solution.py .                                        [100%]

============================== 1 passed in 0.12s ===============================. Error:
test_user,2.2,AssertionError(): test failed: ============================= test session starts ==============================
platform linux -- Python 3.11.4, pytest-7.3.1, pluggy-1.0.0
rootdir: /workspaces/python-challenges
plugins: anyio-4.4.0
collected 1 item

challenges/2.2/test_solution.py .                                        [100%]

============================== 1 passed in 0.12s ===============================. Error:
test_user,2.2,AssertionError(): test failed: .                                                                        [100%]. Error:
test_user,2.2,AssertionError(): test failed: .                                                                        [100%]. Error:
test_user,2.2,AssertionError(): test failed: .                                                                        [100%]. Error:
test_user,2.2,AssertionError(): test failed: .                                                                        [100%]
1 passed in 0.12s. Error:
test_user,2.2,AssertionError(): test failed: ============================= test session starts ==============================
platform linux -- Python 3.11.4, pytest-7.3.1, pluggy-1.0.0 -- /usr/local/py-utils/venvs/pytest/bin/python
cachedir: .pytest_cache
rootdir: /workspaces/python-challenges
plugins: anyio-4.4.0
collecting ... collected 1 item

challenges/2.2/test_solution.py::test_solution PASSED                    [100%]

============================== 1 passed in 0.11s ===============================. Error:
test_user,2.2,AssertionError(): test failed: F                                                                        [100%]
=================================== FAILURES ===================================
________________________________ test_solution _________________________________

user_file = 'user_submissions/test_user/2.2.py'
capsys = <_pytest.capture.CaptureFixture object at 0x773765f86950>

    def test_solution(user_file: str, capsys):
        """run the user submitted code to test it."""
        my_dir, _ = os.path.split(__file__)
        _, my_id = os.path.split(my_dir)
    
    
        challenge_data = challenge_details(my_id)
        startting_code = challenge_data.get("startting_code", '')
        with open(user_file, "rt", encoding='utf-8') as uf:
            code_to_test = uf.read()
        #code_to_test.replace(startting_code, "test_set")
    
        exec(code_to_test)
        captured = capsys.readouterr()
>       assert captured.out == "8\n"
E       AssertionError: assert '' == '8\n'
E         - 8

challenges/2.2/test_solution.py:21: AssertionError
=========================== short test summary info ============================
FAILED challenges/2.2/test_solution.py::test_solution - AssertionError: asser...
1 failed in 0.13s
. Error:
test_user,2.2,Test passed.. Error:
test_user,2.2,Test passed.. Error:
test_user,2.2,AssertionError(): test failed: F                                                                        [100%]
=================================== FAILURES ===================================
________________________________ test_solution _________________________________

user_file = 'user_submissions/test_user/2.2.py'
capsys = <_pytest.capture.CaptureFixture object at 0x782050cbb450>

    def test_solution(user_file: str, capsys):
        """run the user submitted code to test it."""
        my_dir, _ = os.path.split(__file__)
        _, my_id = os.path.split(my_dir)
    
    
        challenge_data = challenge_details(my_id)
        startting_code = challenge_data.get("startting_code", '')
        with open(user_file, "rt", encoding='utf-8') as uf:
            code_to_test = uf.read()
        #code_to_test.replace(startting_code, "test_set")
    
        exec(code_to_test)
        captured = capsys.readouterr()
>       assert captured.out == "8\n"
E       AssertionError: assert '9\n' == '8\n'
E         - 8
E         + 9

challenges/2.2/test_solution.py:21: AssertionError
=========================== short test summary info ============================
FAILED challenges/2.2/test_solution.py::test_solution - AssertionError: asser...
1 failed in 0.16s
. Error:
test_user,2.2,AssertionError(): test failed: F                                                                        [100%]
=================================== FAILURES ===================================
________________________________ test_solution _________________________________

user_file = 'user_submissions/test_user/2.2.py'
capsys = <_pytest.capture.CaptureFixture object at 0x7b3c5bafb550>

    def test_solution(user_file: str, capsys):
        """run the user submitted code to test it."""
        my_dir, _ = os.path.split(__file__)
        _, my_id = os.path.split(my_dir)
    
    
        challenge_data = challenge_details(my_id)
        startting_code = challenge_data.get("startting_code", '')
        with open(user_file, "rt", encoding='utf-8') as uf:
            code_to_test = uf.read()
        #code_to_test.replace(startting_code, "test_set")
    
        exec(code_to_test)
        captured = capsys.readouterr()
>       assert captured.out == "8\n"
E       AssertionError: assert '9\n' == '8\n'
E         - 8
E         + 9

challenges/2.2/test_solution.py:21: AssertionError
=========================== short test summary info ============================
FAILED challenges/2.2/test_solution.py::test_solution - AssertionError: asser...
. Error:
test_user,2.2,AssertionError(): test failed: F                                                                        [100%]
=================================== FAILURES ===================================
________________________________ test_solution _________________________________

user_file = 'user_submissions/test_user/2.2.py'
capsys = <_pytest.capture.CaptureFixture object at 0x721e19770490>

    def test_solution(user_file: str, capsys):
        """run the user submitted code to test it."""
        my_dir, _ = os.path.split(__file__)
        _, my_id = os.path.split(my_dir)
    
    
        challenge_data = challenge_details(my_id)
        startting_code = challenge_data.get("startting_code", '')
        with open(user_file, "rt", encoding='utf-8') as uf:
            code_to_test = uf.read()
        #code_to_test.replace(startting_code, "test_set")
    
        exec(code_to_test)
        captured = capsys.readouterr()
>       assert captured.out == "8\n"
E       AssertionError: assert '9\n' == '8\n'
E         - 8
E         + 9

challenges/2.2/test_solution.py:21: AssertionError
=========================== short test summary info ============================
FAILED challenges/2.2/test_solution.py::test_solution - AssertionError: asser...
. Error:
test_user,2.2,AssertionError(): test failed: F                                                                        [100%]
=================================== FAILURES ===================================
________________________________ test_solution _________________________________

user_file = 'user_submissions/test_user/2.2.py'
capsys = <_pytest.capture.CaptureFixture object at 0x726071ca4b90>

    def test_solution(user_file: str, capsys):
        """run the user submitted code to test it."""
        my_dir, _ = os.path.split(__file__)
        _, my_id = os.path.split(my_dir)
    
    
        challenge_data = challenge_details(my_id)
        startting_code = challenge_data.get("startting_code", '')
        with open(user_file, "rt", encoding='utf-8') as uf:
            code_to_test = uf.read()
        #code_to_test.replace(startting_code, "test_set")
    
        exec(code_to_test)
        captured = capsys.readouterr()
>       assert captured.out == "8\n"
E       AssertionError: assert '9\n' == '8\n'
E         - 8
E         + 9

challenges/2.2/test_solution.py:21: AssertionError
=========================== short test summary info ============================
FAILED challenges/2.2/test_solution.py::test_solution - AssertionError: asser...
. Error:
test_user,2.2,AssertionError(): test failed: F                                                                        [100%]
=================================== FAILURES ===================================
________________________________ test_solution _________________________________

user_file = 'user_submissions/test_user/2.2.py'
capsys = <_pytest.capture.CaptureFixture object at 0x76c5f2e641d0>

    def test_solution(user_file: str, capsys):
        """run the user submitted code to test it."""
        my_dir, _ = os.path.split(__file__)
        _, my_id = os.path.split(my_dir)
    
    
        challenge_data = challenge_details(my_id)
        startting_code = challenge_data.get("startting_code", '')
        with open(user_file, "rt", encoding='utf-8') as uf:
            code_to_test = uf.read()
        #code_to_test.replace(startting_code, "test_set")
    
        exec(code_to_test)
        captured = capsys.readouterr()
>       assert captured.out == "8\n"
E       AssertionError: assert '9\n' == '8\n'
E         - 8
E         + 9

challenges/2.2/test_solution.py:21: AssertionError
=========================== short test summary info ============================
FAILED challenges/2.2/test_solution.py::test_solution - AssertionError: asser...
. Error:
test_user,2.2,AssertionError(): test failed: F                                                                        [100%]
=================================== FAILURES ===================================
/workspaces/python-challenges/challenges/2.2/test_solution.py:21: AssertionError: assert '9\n' == '8\n'
=========================== short test summary info ============================
FAILED challenges/2.2/test_solution.py::test_solution - AssertionError: asser...
. Error:
test_user,2.2,Test passed.. Error:
test_user,2.2,AssertionError(): test failed: F                                                                        [100%]
=========================== short test summary info ============================
FAILED challenges/2.2/test_solution.py::test_solution - AssertionError: asser...
. Error:
test_user,2.2,AssertionError(): test failed: F                                                                        [100%]
=================================== FAILURES ===================================
________________________________ test_solution _________________________________
challenges/2.2/test_solution.py:21: in test_solution
    assert captured.out == "8\n"
E   AssertionError: assert '9\n' == '8\n'
E     - 8
E     + 9
=========================== short test summary info ============================
FAILED challenges/2.2/test_solution.py::test_solution - AssertionError: asser...
. Error:
test_user,2.2,AssertionError(): test failed: F                                                                        [100%]
=================================== FAILURES ===================================
________________________________ test_solution _________________________________
challenges/2.2/test_solution.py:23: in test_solution
    assert received == expected_output
E   AssertionError: assert '9\n' == '8\n'
E     - 8
E     + 9
=========================== short test summary info ============================
FAILED challenges/2.2/test_solution.py::test_solution - AssertionError: asser...
. Error:
test_user,2.2,AssertionError(): test failed: FF                                                                       [100%]
=================================== FAILURES ===================================
_______________________ test_solution[a=1\nb=2\nc=3\n-6] _______________________
challenges/2.2/test_solution.py:28: in test_solution
    assert received == expected_output
E   AssertionError: assert '9\n' == 6
______________________ test_solution[a=10\nb=11\nc=12-36] ______________________
challenges/2.2/test_solution.py:24: in test_solution
    exec(code_to_test)
E     File "<string>", line 3
E       c=12print(9)
E          ^
E   SyntaxError: invalid decimal literal
=========================== short test summary info ============================
FAILED challenges/2.2/test_solution.py::test_solution[a=1\nb=2\nc=3\n-6] - As...
FAILED challenges/2.2/test_solution.py::test_solution[a=10\nb=11\nc=12-36] - ...
. Error:
test_user,2.2,AssertionError(): test failed: FF                                                                       [100%]
=================================== FAILURES ===================================
_______________________ test_solution[a=1\nb=2\nc=3\n-6] _______________________
challenges/2.2/test_solution.py:28: in test_solution
    assert received == expected_output
E   AssertionError: assert '9\n' == 6
_____________________ test_solution[a=10\nb=11\nc=12\n-36] _____________________
challenges/2.2/test_solution.py:28: in test_solution
    assert received == expected_output
E   AssertionError: assert '9\n' == 36
=========================== short test summary info ============================
FAILED challenges/2.2/test_solution.py::test_solution[a=1\nb=2\nc=3\n-6] - As...
FAILED challenges/2.2/test_solution.py::test_solution[a=10\nb=11\nc=12\n-36]
. Error:
test_user,2.2,AssertionError(): test failed: FF                                                                       [100%]
=================================== FAILURES ===================================
_______________________ test_solution[a=1\nb=2\nc=3\n-6] _______________________
challenges/2.2/test_solution.py:28: in test_solution
    assert received == expected_output
E   AssertionError: assert '6\n' == 6
_____________________ test_solution[a=10\nb=11\nc=12\n-36] _____________________
challenges/2.2/test_solution.py:28: in test_solution
    assert received == expected_output
E   AssertionError: assert '33\n' == 36
=========================== short test summary info ============================
FAILED challenges/2.2/test_solution.py::test_solution[a=1\nb=2\nc=3\n-6] - As...
FAILED challenges/2.2/test_solution.py::test_solution[a=10\nb=11\nc=12\n-36]
. Error:
test_user,2.2,AssertionError(): test failed: FF                                                                       [100%]
=================================== FAILURES ===================================
_______________________ test_solution[a=1\nb=2\nc=3\n-6] _______________________
challenges/2.2/test_solution.py:28: in test_solution
    assert received == expected_output+"\n"
E   TypeError: unsupported operand type(s) for +: 'int' and 'str'
_____________________ test_solution[a=10\nb=11\nc=12\n-33] _____________________
challenges/2.2/test_solution.py:28: in test_solution
    assert received == expected_output+"\n"
E   TypeError: unsupported operand type(s) for +: 'int' and 'str'
=========================== short test summary info ============================
FAILED challenges/2.2/test_solution.py::test_solution[a=1\nb=2\nc=3\n-6] - Ty...
FAILED challenges/2.2/test_solution.py::test_solution[a=10\nb=11\nc=12\n-33]
. Error:
test_user,2.2,Test passed.. Error:
test_user,2.2,AssertionError(): test failed: FF                                                                       [100%]
=================================== FAILURES ===================================
_______________________ test_solution[a=1\nb=2\nc=3\n-6] _______________________
challenges/2.2/test_solution.py:28: in test_solution
    assert received == f"{expected_output}\n"
E   AssertionError: assert '7\n' == '6\n'
E     - 6
E     + 7
_____________________ test_solution[a=10\nb=11\nc=12\n-33] _____________________
challenges/2.2/test_solution.py:28: in test_solution
    assert received == f"{expected_output}\n"
E   AssertionError: assert '34\n' == '33\n'
E     - 33
E     + 34
=========================== short test summary info ============================
FAILED challenges/2.2/test_solution.py::test_solution[a=1\nb=2\nc=3\n-6] - As...
FAILED challenges/2.2/test_solution.py::test_solution[a=10\nb=11\nc=12\n-33]
. Error:
test_user,2.2,Test passed.. Error:
test_user,2.2,AssertionError(): test failed: .F                                                                       [100%]
=================================== FAILURES ===================================
_____________________ test_solution[a=10\nb=11\nc=12\n-33] _____________________
challenges/2.2/test_solution.py:28: in test_solution
    assert received == f"{expected_output}\n"
E   AssertionError: assert '15\n' == '33\n'
E     - 33
E     + 15
=========================== short test summary info ============================
FAILED challenges/2.2/test_solution.py::test_solution[a=10\nb=11\nc=12\n-33]
. Error:
test_user,2.2,AssertionError(): test failed: FF                                                                       [100%]
=================================== FAILURES ===================================
_______________________ test_solution[a=1\nb=2\nc=3\n-6] _______________________
challenges/2.2/test_solution.py:28: in test_solution
    assert received == f"{expected_output}\n"
E   AssertionError: assert '' == '6\n'
E     - 6
_____________________ test_solution[a=10\nb=11\nc=12\n-33] _____________________
challenges/2.2/test_solution.py:28: in test_solution
    assert received == f"{expected_output}\n"
E   AssertionError: assert '' == '33\n'
E     - 33
=========================== short test summary info ============================
FAILED challenges/2.2/test_solution.py::test_solution[a=1\nb=2\nc=3\n-6] - As...
FAILED challenges/2.2/test_solution.py::test_solution[a=10\nb=11\nc=12\n-33]
. Error:
test_user,2.2,AssertionError(): test failed: FF                                                                       [100%]
=================================== FAILURES ===================================
_______________________ test_solution[a=1\nb=2\nc=3\n-6] _______________________
challenges/2.2/test_solution.py:28: in test_solution
    assert received == f"{expected_output}\n"
E   AssertionError: assert '' == '6\n'
E     
E     - 6
_____________________ test_solution[a=10\nb=11\nc=12\n-33] _____________________
challenges/2.2/test_solution.py:28: in test_solution
    assert received == f"{expected_output}\n"
E   AssertionError: assert '' == '33\n'
E     
E     - 33
=========================== short test summary info ============================
FAILED challenges/2.2/test_solution.py::test_solution[a=1\nb=2\nc=3\n-6] - As...
FAILED challenges/2.2/test_solution.py::test_solution[a=10\nb=11\nc=12\n-33]
. Error:
test_user,2.2,AssertionError(): test failed: FF                                                                       [100%]
=================================== FAILURES ===================================
_______________________ test_solution[a=1\nb=2\nc=3\n-6] _______________________
challenges/2.2/test_solution.py:28: in test_solution
    assert received == f"{expected_output}\n"
E   AssertionError: assert '' == '6\n'
E     
E     - 6
_____________________ test_solution[a=10\nb=11\nc=12\n-33] _____________________
challenges/2.2/test_solution.py:28: in test_solution
    assert received == f"{expected_output}\n"
E   AssertionError: assert '' == '33\n'
E     
E     - 33
=========================== short test summary info ============================
FAILED challenges/2.2/test_solution.py::test_solution[a=1\nb=2\nc=3\n-6] - As...
FAILED challenges/2.2/test_solution.py::test_solution[a=10\nb=11\nc=12\n-33]
. Error:
test_user,2.2,AssertionError(): test failed: FF                                                                       [100%]
=================================== FAILURES ===================================
_______________________ test_solution[a=1\nb=2\nc=3\n-6] _______________________
challenges/2.2/test_solution.py:28: in test_solution
    assert received == f"{expected_output}\n"
E   AssertionError: assert '' == '6\n'
E     
E     - 6
_____________________ test_solution[a=10\nb=11\nc=12\n-33] _____________________
challenges/2.2/test_solution.py:28: in test_solution
    assert received == f"{expected_output}\n"
E   AssertionError: assert '' == '33\n'
E     
E     - 33
=========================== short test summary info ============================
FAILED challenges/2.2/test_solution.py::test_solution[a=1\nb=2\nc=3\n-6] - As...
FAILED challenges/2.2/test_solution.py::test_solution[a=10\nb=11\nc=12\n-33]
. Error:
test_user,2.2,. Error:test failed: FF                                                                       [100%]
=================================== FAILURES ===================================
_______________________ test_solution[a=1\nb=2\nc=3\n-6] _______________________
challenges/2.2/test_solution.py:28: in test_solution
    assert received == f"{expected_output}\n"
E   AssertionError: assert '' == '6\n'
E     
E     - 6
_____________________ test_solution[a=10\nb=11\nc=12\n-33] _____________________
challenges/2.2/test_solution.py:28: in test_solution
    assert received == f"{expected_output}\n"
E   AssertionError: assert '' == '33\n'
E     
E     - 33
=========================== short test summary info ============================
FAILED challenges/2.2/test_solution.py::test_solution[a=1\nb=2\nc=3\n-6] - As...
FAILED challenges/2.2/test_solution.py::test_solution[a=10\nb=11\nc=12\n-33]

test_user,2.2,. Error:test failed: FF                                                                       [100%]
=================================== FAILURES ===================================
_______________________ test_solution[a=1\nb=2\nc=3\n-6] _______________________
challenges/2.2/test_solution.py:28: in test_solution
    assert received == f"{expected_output}\n"
E   AssertionError: assert '' == '6\n'
E     
E     - 6
_____________________ test_solution[a=10\nb=11\nc=12\n-33] _____________________
challenges/2.2/test_solution.py:28: in test_solution
    assert received == f"{expected_output}\n"
E   AssertionError: assert '' == '33\n'
E     
E     - 33
=========================== short test summary info ============================
FAILED challenges/2.2/test_solution.py::test_solution[a=1\nb=2\nc=3\n-6] - As...
FAILED challenges/2.2/test_solution.py::test_solution[a=10\nb=11\nc=12\n-33]

test_user,2.2,. Error:test failed: 
FF                                                                       [100%]
=================================== FAILURES ===================================
_______________________ test_solution[a=1\nb=2\nc=3\n-6] _______________________
challenges/2.2/test_solution.py:28: in test_solution
    assert received == f"{expected_output}\n"
E   AssertionError: assert '' == '6\n'
E     
E     - 6
_____________________ test_solution[a=10\nb=11\nc=12\n-33] _____________________
challenges/2.2/test_solution.py:28: in test_solution
    assert received == f"{expected_output}\n"
E   AssertionError: assert '' == '33\n'
E     
E     - 33
=========================== short test summary info ============================
FAILED challenges/2.2/test_solution.py::test_solution[a=1\nb=2\nc=3\n-6] - As...
FAILED challenges/2.2/test_solution.py::test_solution[a=10\nb=11\nc=12\n-33]

test_user,2.2,. Error:test failed: 
FF                                                                       [100%]
=================================== FAILURES ===================================
_______________________ test_solution[a=1\nb=2\nc=3\n-6] _______________________
challenges/2.2/test_solution.py:27: in test_solution
    assert received == expected_output
E   AssertionError: assert '' == 6
_____________________ test_solution[a=10\nb=11\nc=12\n-33] _____________________
challenges/2.2/test_solution.py:27: in test_solution
    assert received == expected_output
E   AssertionError: assert '' == 33
=========================== short test summary info ============================
FAILED challenges/2.2/test_solution.py::test_solution[a=1\nb=2\nc=3\n-6] - As...
FAILED challenges/2.2/test_solution.py::test_solution[a=10\nb=11\nc=12\n-33]

test_user,2.2,. Error:test failed: 
FF                                                                       [100%]
=================================== FAILURES ===================================
_______________________ test_solution[a=1\nb=2\nc=3\n-6] _______________________
challenges/2.2/test_solution.py:27: in test_solution
    assert received == expected_output
E   AssertionError: assert '' == 6
_____________________ test_solution[a=10\nb=11\nc=12\n-33] _____________________
challenges/2.2/test_solution.py:27: in test_solution
    assert received == expected_output
E   AssertionError: assert '' == 33
=========================== short test summary info ============================
FAILED challenges/2.2/test_solution.py::test_solution[a=1\nb=2\nc=3\n-6] - As...
FAILED challenges/2.2/test_solution.py::test_solution[a=10\nb=11\nc=12\n-33]

test_user,2.2,. Error:test failed: 
FF                                                                       [100%]
=================================== FAILURES ===================================
_______________________ test_solution[a=1\nb=2\nc=3\n-6] _______________________
challenges/2.2/test_solution.py:27: in test_solution
    assert received == expected_output
E   AssertionError: assert '' == 6
_____________________ test_solution[a=10\nb=11\nc=12\n-33] _____________________
challenges/2.2/test_solution.py:27: in test_solution
    assert received == expected_output
E   AssertionError: assert '' == 33
=========================== short test summary info ============================
FAILED challenges/2.2/test_solution.py::test_solution[a=1\nb=2\nc=3\n-6] - As...
FAILED challenges/2.2/test_solution.py::test_solution[a=10\nb=11\nc=12\n-33]

test_user,2.2,. Error:test failed: 
FF                                                                       [100%]
=================================== FAILURES ===================================
_______________________ test_solution[a=1\nb=2\nc=3\n-6] _______________________
challenges/2.2/test_solution.py:27: in test_solution
    assert received == expected_output
E   AssertionError: assert '' == 6
_____________________ test_solution[a=10\nb=11\nc=12\n-33] _____________________
challenges/2.2/test_solution.py:27: in test_solution
    assert received == expected_output
E   AssertionError: assert '' == 33
=========================== short test summary info ============================
FAILED challenges/2.2/test_solution.py::test_solution[a=1\nb=2\nc=3\n-6] - As...
FAILED challenges/2.2/test_solution.py::test_solution[a=10\nb=11\nc=12\n-33]

test_user,2.2,. Error:test failed: 
FF                                                                       [100%]
=================================== FAILURES ===================================
_______________________ test_solution[a=1\nb=2\nc=3\n-6] _______________________
challenges/2.2/test_solution.py:27: in test_solution
    assert received == expected_output
E   AssertionError: assert '' == 6
_____________________ test_solution[a=10\nb=11\nc=12\n-33] _____________________
challenges/2.2/test_solution.py:27: in test_solution
    assert received == expected_output
E   AssertionError: assert '' == 33
=========================== short test summary info ============================
FAILED challenges/2.2/test_solution.py::test_solution[a=1\nb=2\nc=3\n-6] - As...
FAILED challenges/2.2/test_solution.py::test_solution[a=10\nb=11\nc=12\n-33]

test_user,2.2,. Error:test failed: 
FF                                                                       [100%]
=================================== FAILURES ===================================
_______________________ test_solution[a=1\nb=2\nc=3\n-6] _______________________
challenges/2.2/test_solution.py:27: in test_solution
    assert received == expected_output
E   AssertionError: assert '' == 6
_____________________ test_solution[a=10\nb=11\nc=12\n-33] _____________________
challenges/2.2/test_solution.py:27: in test_solution
    assert received == expected_output
E   AssertionError: assert '' == 33
=========================== short test summary info ============================
FAILED challenges/2.2/test_solution.py::test_solution[a=1\nb=2\nc=3\n-6] - As...
FAILED challenges/2.2/test_solution.py::test_solution[a=10\nb=11\nc=12\n-33]

test_user,2.2,. Error:test failed: 
FF                                                                       [100%]
=================================== FAILURES ===================================
_______________________ test_solution[a=1\nb=2\nc=3\n-6] _______________________
challenges/2.2/test_solution.py:27: in test_solution
    assert received == expected_output
E   AssertionError: assert '' == 6
_____________________ test_solution[a=10\nb=11\nc=12\n-33] _____________________
challenges/2.2/test_solution.py:27: in test_solution
    assert received == expected_output
E   AssertionError: assert '' == 33
=========================== short test summary info ============================
FAILED challenges/2.2/test_solution.py::test_solution[a=1\nb=2\nc=3\n-6] - As...
FAILED challenges/2.2/test_solution.py::test_solution[a=10\nb=11\nc=12\n-33]
test_user,2.2,. Error:test failed: 
FF                                                                       [100%]
=================================== FAILURES ===================================
_______________________ test_solution[a=1\nb=2\nc=3\n-6] _______________________
challenges/2.2/test_solution.py:27: in test_solution
    assert received == expected_output
E   AssertionError: assert '' == 6
_____________________ test_solution[a=10\nb=11\nc=12\n-33] _____________________
challenges/2.2/test_solution.py:27: in test_solution
    assert received == expected_output
E   AssertionError: assert '' == 33
=========================== short test summary info ============================
FAILED challenges/2.2/test_solution.py::test_solution[a=1\nb=2\nc=3\n-6] - As...
FAILED challenges/2.2/test_solution.py::test_solution[a=10\nb=11\nc=12\n-33]
test_user,2.2,. Error:test failed: 
FF                                                                       [100%]
=================================== FAILURES ===================================
_______________________ test_solution[a=1\nb=2\nc=3\n-6] _______________________
challenges/2.2/test_solution.py:27: in test_solution
    assert received == expected_output
E   AssertionError: assert '' == 6
_____________________ test_solution[a=10\nb=11\nc=12\n-33] _____________________
challenges/2.2/test_solution.py:27: in test_solution
    assert received == expected_output
E   AssertionError: assert '' == 33
=========================== short test summary info ============================
FAILED challenges/2.2/test_solution.py::test_solution[a=1\nb=2\nc=3\n-6] - As...
FAILED challenges/2.2/test_solution.py::test_solution[a=10\nb=11\nc=12\n-33]
test_user,2.2,. Error:test failed: 
FF                                                                       [100%]
=================================== FAILURES ===================================
_______________________ test_solution[a=1\nb=2\nc=3\n-6] _______________________
challenges/2.2/test_solution.py:27: in test_solution
    assert received == expected_output
E   AssertionError: assert '' == 6
_____________________ test_solution[a=10\nb=11\nc=12\n-33] _____________________
challenges/2.2/test_solution.py:27: in test_solution
    assert received == expected_output
E   AssertionError: assert '' == 33
=========================== short test summary info ============================
FAILED challenges/2.2/test_solution.py::test_solution[a=1\nb=2\nc=3\n-6] - As...
FAILED challenges/2.2/test_solution.py::test_solution[a=10\nb=11\nc=12\n-33]
test_user,2.2,. Error:test failed: 
FF                                                                       [100%]
=================================== FAILURES ===================================
_______________________ test_solution[a=1\nb=2\nc=3\n-6] _______________________
challenges/2.2/test_solution.py:27: in test_solution
    assert received == expected_output
E   AssertionError: assert '' == 6
_____________________ test_solution[a=10\nb=11\nc=12\n-33] _____________________
challenges/2.2/test_solution.py:27: in test_solution
    assert received == expected_output
E   AssertionError: assert '' == 33
=========================== short test summary info ============================
FAILED challenges/2.2/test_solution.py::test_solution[a=1\nb=2\nc=3\n-6] - As...
FAILED challenges/2.2/test_solution.py::test_solution[a=10\nb=11\nc=12\n-33]
test_user,2.2,. Error:test failed: 
FF                                                                       [100%]
=================================== FAILURES ===================================
_______________________ test_solution[a=1\nb=2\nc=3\n-6] _______________________
challenges/2.2/test_solution.py:27: in test_solution
    assert received == expected_output
E   AssertionError: assert '' == 6
_____________________ test_solution[a=10\nb=11\nc=12\n-33] _____________________
challenges/2.2/test_solution.py:27: in test_solution
    assert received == expected_output
E   AssertionError: assert '' == 33
=========================== short test summary info ============================
FAILED challenges/2.2/test_solution.py::test_solution[a=1\nb=2\nc=3\n-6] - As...
FAILED challenges/2.2/test_solution.py::test_solution[a=10\nb=11\nc=12\n-33]
test_user,2.2,. Error:test failed: 
FF                                                                       [100%]
=================================== FAILURES ===================================
_______________________ test_solution[a=1\nb=2\nc=3\n-6] _______________________
challenges/2.2/test_solution.py:27: in test_solution
    assert received == expected_output
E   AssertionError: assert '' == 6
_____________________ test_solution[a=10\nb=11\nc=12\n-33] _____________________
challenges/2.2/test_solution.py:27: in test_solution
    assert received == expected_output
E   AssertionError: assert '' == 33
=========================== short test summary info ============================
FAILED challenges/2.2/test_solution.py::test_solution[a=1\nb=2\nc=3\n-6] - As...
FAILED challenges/2.2/test_solution.py::test_solution[a=10\nb=11\nc=12\n-33]
test_user,2.2,. Error:test failed: 
FF                                                                       [100%]
=================================== FAILURES ===================================
_______________________ test_solution[a=1\nb=2\nc=3\n-6] _______________________
challenges/2.2/test_solution.py:27: in test_solution
    assert received == expected_output
E   AssertionError: assert '' == 6
_____________________ test_solution[a=10\nb=11\nc=12\n-33] _____________________
challenges/2.2/test_solution.py:27: in test_solution
    assert received == expected_output
E   AssertionError: assert '' == 33
=========================== short test summary info ============================
FAILED challenges/2.2/test_solution.py::test_solution[a=1\nb=2\nc=3\n-6] - As...
FAILED challenges/2.2/test_solution.py::test_solution[a=10\nb=11\nc=12\n-33]
test_user,2.2,. Error:test failed: 
FF                                                                       [100%]
=================================== FAILURES ===================================
_______________________ test_solution[a=1\nb=2\nc=3\n-6] _______________________
challenges/2.2/test_solution.py:27: in test_solution
    assert received == expected_output
E   AssertionError: assert '' == 6
_____________________ test_solution[a=10\nb=11\nc=12\n-33] _____________________
challenges/2.2/test_solution.py:27: in test_solution
    assert received == expected_output
E   AssertionError: assert '' == 33
=========================== short test summary info ============================
FAILED challenges/2.2/test_solution.py::test_solution[a=1\nb=2\nc=3\n-6] - As...
FAILED challenges/2.2/test_solution.py::test_solution[a=10\nb=11\nc=12\n-33]
test_user,2.2,. Error:test failed: 
FF                                                                       [100%]
=================================== FAILURES ===================================
_______________________ test_solution[a=1\nb=2\nc=3\n-6] _______________________
challenges/2.2/test_solution.py:27: in test_solution
    assert received == expected_output
E   AssertionError: assert '' == 6
_____________________ test_solution[a=10\nb=11\nc=12\n-33] _____________________
challenges/2.2/test_solution.py:27: in test_solution
    assert received == expected_output
E   AssertionError: assert '' == 33
=========================== short test summary info ============================
FAILED challenges/2.2/test_solution.py::test_solution[a=1\nb=2\nc=3\n-6] - As...
FAILED challenges/2.2/test_solution.py::test_solution[a=10\nb=11\nc=12\n-33]
test_user,2.2,. Error:test failed: 
FF                                                                       [100%]
=================================== FAILURES ===================================
_______________________ test_solution[a=1\nb=2\nc=3\n-6] _______________________
challenges/2.2/test_solution.py:27: in test_solution
    assert received == expected_output
E   AssertionError: assert '' == 6
_____________________ test_solution[a=10\nb=11\nc=12\n-33] _____________________
challenges/2.2/test_solution.py:27: in test_solution
    assert received == expected_output
E   AssertionError: assert '' == 33
=========================== short test summary info ============================
FAILED challenges/2.2/test_solution.py::test_solution[a=1\nb=2\nc=3\n-6] - As...
FAILED challenges/2.2/test_solution.py::test_solution[a=10\nb=11\nc=12\n-33]
test_user,2.2,. Error:test failed: 
FF                                                                       [100%]
=================================== FAILURES ===================================
_______________________ test_solution[a=1\nb=2\nc=3\n-6] _______________________
challenges/2.2/test_solution.py:27: in test_solution
    assert received == expected_output
E   AssertionError: assert '' == 6
_____________________ test_solution[a=10\nb=11\nc=12\n-33] _____________________
challenges/2.2/test_solution.py:27: in test_solution
    assert received == expected_output
E   AssertionError: assert '' == 33
=========================== short test summary info ============================
FAILED challenges/2.2/test_solution.py::test_solution[a=1\nb=2\nc=3\n-6] - As...
FAILED challenges/2.2/test_solution.py::test_solution[a=10\nb=11\nc=12\n-33]
test_user,2.2,. Error:test failed: 
FF                                                                       [100%]
=================================== FAILURES ===================================
_______________________ test_solution[a=1\nb=2\nc=3\n-6] _______________________
challenges/2.2/test_solution.py:27: in test_solution
    assert received == expected_output
E   AssertionError: assert '' == 6
_____________________ test_solution[a=10\nb=11\nc=12\n-33] _____________________
challenges/2.2/test_solution.py:27: in test_solution
    assert received == expected_output
E   AssertionError: assert '' == 33
=========================== short test summary info ============================
FAILED challenges/2.2/test_solution.py::test_solution[a=1\nb=2\nc=3\n-6] - As...
FAILED challenges/2.2/test_solution.py::test_solution[a=10\nb=11\nc=12\n-33]
test_user,2.2,. Error:test failed: 
FF                                                                       [100%]
=================================== FAILURES ===================================
_______________________ test_solution[a=1\nb=2\nc=3\n-6] _______________________
challenges/2.2/test_solution.py:27: in test_solution
    assert received == expected_output
E   AssertionError: assert '' == 6
_____________________ test_solution[a=10\nb=11\nc=12\n-33] _____________________
challenges/2.2/test_solution.py:27: in test_solution
    assert received == expected_output
E   AssertionError: assert '' == 33
=========================== short test summary info ============================
FAILED challenges/2.2/test_solution.py::test_solution[a=1\nb=2\nc=3\n-6] - As...
FAILED challenges/2.2/test_solution.py::test_solution[a=10\nb=11\nc=12\n-33]
test_user,2.2,. Error:test failed: 
FF                                                                       [100%]
=================================== FAILURES ===================================
_______________________ test_solution[a=1\nb=2\nc=3\n-6] _______________________
challenges/2.2/test_solution.py:27: in test_solution
    assert received == expected_output
E   AssertionError: assert '' == 6
_____________________ test_solution[a=10\nb=11\nc=12\n-33] _____________________
challenges/2.2/test_solution.py:27: in test_solution
    assert received == expected_output
E   AssertionError: assert '' == 33
=========================== short test summary info ============================
FAILED challenges/2.2/test_solution.py::test_solution[a=1\nb=2\nc=3\n-6] - As...
FAILED challenges/2.2/test_solution.py::test_solution[a=10\nb=11\nc=12\n-33]
test_user,2.2,. Error:test failed: 
FF                                                                       [100%]
=================================== FAILURES ===================================
_______________________ test_solution[a=1\nb=2\nc=3\n-6] _______________________
challenges/2.2/test_solution.py:27: in test_solution
    assert received == expected_output
E   AssertionError: assert '' == 6
_____________________ test_solution[a=10\nb=11\nc=12\n-33] _____________________
challenges/2.2/test_solution.py:27: in test_solution
    assert received == expected_output
E   AssertionError: assert '' == 33
=========================== short test summary info ============================
FAILED challenges/2.2/test_solution.py::test_solution[a=1\nb=2\nc=3\n-6] - As...
FAILED challenges/2.2/test_solution.py::test_solution[a=10\nb=11\nc=12\n-33]
test_user,2.2,. Error:test failed: 
FF                                                                       [100%]
=================================== FAILURES ===================================
_______________________ test_solution[a=1\nb=2\nc=3\n-6] _______________________
challenges/2.2/test_solution.py:27: in test_solution
    assert received == expected_output
E   AssertionError: assert '' == 6
_____________________ test_solution[a=10\nb=11\nc=12\n-33] _____________________
challenges/2.2/test_solution.py:27: in test_solution
    assert received == expected_output
E   AssertionError: assert '' == 33
=========================== short test summary info ============================
FAILED challenges/2.2/test_solution.py::test_solution[a=1\nb=2\nc=3\n-6] - As...
FAILED challenges/2.2/test_solution.py::test_solution[a=10\nb=11\nc=12\n-33]
test_user,2.2,. Error:test failed: 
FF                                                                       [100%]
=================================== FAILURES ===================================
_______________________ test_solution[a=1\nb=2\nc=3\n-6] _______________________
challenges/2.2/test_solution.py:27: in test_solution
    assert received == expected_output
E   AssertionError: assert '' == 6
_____________________ test_solution[a=10\nb=11\nc=12\n-33] _____________________
challenges/2.2/test_solution.py:27: in test_solution
    assert received == expected_output
E   AssertionError: assert '' == 33
=========================== short test summary info ============================
FAILED challenges/2.2/test_solution.py::test_solution[a=1\nb=2\nc=3\n-6] - As...
FAILED challenges/2.2/test_solution.py::test_solution[a=10\nb=11\nc=12\n-33]
test_user,2.2,. Error:test failed: 
FF                                                                       [100%]
=================================== FAILURES ===================================
_______________________ test_solution[a=1\nb=2\nc=3\n-6] _______________________
challenges/2.2/test_solution.py:27: in test_solution
    assert received == expected_output
E   AssertionError: assert '' == 6
_____________________ test_solution[a=10\nb=11\nc=12\n-33] _____________________
challenges/2.2/test_solution.py:27: in test_solution
    assert received == expected_output
E   AssertionError: assert '' == 33
=========================== short test summary info ============================
FAILED challenges/2.2/test_solution.py::test_solution[a=1\nb=2\nc=3\n-6] - As...
FAILED challenges/2.2/test_solution.py::test_solution[a=10\nb=11\nc=12\n-33]
test_user,2.2,. Error:test failed: 
FF                                                                       [100%]
=================================== FAILURES ===================================
_______________________ test_solution[a=1\nb=2\nc=3\n-6] _______________________
challenges/2.2/test_solution.py:27: in test_solution
    assert received == expected_output
E   AssertionError: assert '' == 6
_____________________ test_solution[a=10\nb=11\nc=12\n-33] _____________________
challenges/2.2/test_solution.py:27: in test_solution
    assert received == expected_output
E   AssertionError: assert '' == 33
=========================== short test summary info ============================
FAILED challenges/2.2/test_solution.py::test_solution[a=1\nb=2\nc=3\n-6] - As...
FAILED challenges/2.2/test_solution.py::test_solution[a=10\nb=11\nc=12\n-33]
test_user,2.2,. Error:test failed: 
FF                                                                       [100%]
=================================== FAILURES ===================================
_______________________ test_solution[a=1\nb=2\nc=3\n-6] _______________________
challenges/2.2/test_solution.py:27: in test_solution
    assert received == expected_output
E   AssertionError: assert '' == 6
_____________________ test_solution[a=10\nb=11\nc=12\n-33] _____________________
challenges/2.2/test_solution.py:27: in test_solution
    assert received == expected_output
E   AssertionError: assert '' == 33
=========================== short test summary info ============================
FAILED challenges/2.2/test_solution.py::test_solution[a=1\nb=2\nc=3\n-6] - As...
FAILED challenges/2.2/test_solution.py::test_solution[a=10\nb=11\nc=12\n-33]
test_user,2.2,. Error:test failed: 
FF                                                                       [100%]
=================================== FAILURES ===================================
_______________________ test_solution[a=1\nb=2\nc=3\n-6] _______________________
challenges/2.2/test_solution.py:27: in test_solution
    assert received == expected_output
E   AssertionError: assert '' == 6
_____________________ test_solution[a=10\nb=11\nc=12\n-33] _____________________
challenges/2.2/test_solution.py:27: in test_solution
    assert received == expected_output
E   AssertionError: assert '' == 33
=========================== short test summary info ============================
FAILED challenges/2.2/test_solution.py::test_solution[a=1\nb=2\nc=3\n-6] - As...
FAILED challenges/2.2/test_solution.py::test_solution[a=10\nb=11\nc=12\n-33]
test_user,2.2,. Error:test failed: 
FF                                                                       [100%]
=================================== FAILURES ===================================
_______________________ test_solution[a=1\nb=2\nc=3\n-6] _______________________
challenges/2.2/test_solution.py:27: in test_solution
    assert received == expected_output
E   AssertionError: assert '' == 6
_____________________ test_solution[a=10\nb=11\nc=12\n-33] _____________________
challenges/2.2/test_solution.py:27: in test_solution
    assert received == expected_output
E   AssertionError: assert '' == 33
=========================== short test summary info ============================
FAILED challenges/2.2/test_solution.py::test_solution[a=1\nb=2\nc=3\n-6] - As...
FAILED challenges/2.2/test_solution.py::test_solution[a=10\nb=11\nc=12\n-33]
test_user,2.2,. Error:test failed: 
FF                                                                       [100%]
=================================== FAILURES ===================================
_______________________ test_solution[a=1\nb=2\nc=3\n-6] _______________________
challenges/2.2/test_solution.py:27: in test_solution
    assert received == expected_output
E   AssertionError: assert '' == 6
_____________________ test_solution[a=10\nb=11\nc=12\n-33] _____________________
challenges/2.2/test_solution.py:27: in test_solution
    assert received == expected_output
E   AssertionError: assert '' == 33
=========================== short test summary info ============================
FAILED challenges/2.2/test_solution.py::test_solution[a=1\nb=2\nc=3\n-6] - As...
FAILED challenges/2.2/test_solution.py::test_solution[a=10\nb=11\nc=12\n-33]
test_user,2.2,. Error:test failed: 
FF                                                                       [100%]
=================================== FAILURES ===================================
_______________________ test_solution[a=1\nb=2\nc=3\n-6] _______________________
challenges/2.2/test_solution.py:27: in test_solution
    assert received == expected_output
E   AssertionError: assert '' == 6
_____________________ test_solution[a=10\nb=11\nc=12\n-33] _____________________
challenges/2.2/test_solution.py:27: in test_solution
    assert received == expected_output
E   AssertionError: assert '' == 33
=========================== short test summary info ============================
FAILED challenges/2.2/test_solution.py::test_solution[a=1\nb=2\nc=3\n-6] - As...
FAILED challenges/2.2/test_solution.py::test_solution[a=10\nb=11\nc=12\n-33]
test_user,2.2,. Error:test failed: 
FF                                                                       [100%]
=================================== FAILURES ===================================
_______________________ test_solution[a=1\nb=2\nc=3\n-6] _______________________
challenges/2.2/test_solution.py:27: in test_solution
    assert received == expected_output
E   AssertionError: assert '' == 6
_____________________ test_solution[a=10\nb=11\nc=12\n-33] _____________________
challenges/2.2/test_solution.py:27: in test_solution
    assert received == expected_output
E   AssertionError: assert '' == 33
=========================== short test summary info ============================
FAILED challenges/2.2/test_solution.py::test_solution[a=1\nb=2\nc=3\n-6] - As...
FAILED challenges/2.2/test_solution.py::test_solution[a=10\nb=11\nc=12\n-33]
test_user,2.2,. Error:test failed: 
FF                                                                       [100%]
=================================== FAILURES ===================================
_______________________ test_solution[a=1\nb=2\nc=3\n-6] _______________________
challenges/2.2/test_solution.py:27: in test_solution
    assert received == expected_output
E   AssertionError: assert '' == 6
_____________________ test_solution[a=10\nb=11\nc=12\n-33] _____________________
challenges/2.2/test_solution.py:27: in test_solution
    assert received == expected_output
E   AssertionError: assert '' == 33
=========================== short test summary info ============================
FAILED challenges/2.2/test_solution.py::test_solution[a=1\nb=2\nc=3\n-6] - As...
FAILED challenges/2.2/test_solution.py::test_solution[a=10\nb=11\nc=12\n-33]
test_user,2.2,. Error:test failed: 
FF                                                                       [100%]
=================================== FAILURES ===================================
_______________________ test_solution[a=1\nb=2\nc=3\n-6] _______________________
challenges/2.2/test_solution.py:27: in test_solution
    assert received == expected_output
E   AssertionError: assert '' == 6
_____________________ test_solution[a=10\nb=11\nc=12\n-33] _____________________
challenges/2.2/test_solution.py:27: in test_solution
    assert received == expected_output
E   AssertionError: assert '' == 33
=========================== short test summary info ============================
FAILED challenges/2.2/test_solution.py::test_solution[a=1\nb=2\nc=3\n-6] - As...
FAILED challenges/2.2/test_solution.py::test_solution[a=10\nb=11\nc=12\n-33]
test_user,2.2,. Error:test failed: 
FF                                                                       [100%]
=================================== FAILURES ===================================
_______________________ test_solution[a=1\nb=2\nc=3\n-6] _______________________
challenges/2.2/test_solution.py:27: in test_solution
    assert received == expected_output
E   AssertionError: assert '' == 6
_____________________ test_solution[a=10\nb=11\nc=12\n-33] _____________________
challenges/2.2/test_solution.py:27: in test_solution
    assert received == expected_output
E   AssertionError: assert '' == 33
=========================== short test summary info ============================
FAILED challenges/2.2/test_solution.py::test_solution[a=1\nb=2\nc=3\n-6] - As...
FAILED challenges/2.2/test_solution.py::test_solution[a=10\nb=11\nc=12\n-33]
test_user,2.2,. Error:test failed: 
FF                                                                       [100%]
=================================== FAILURES ===================================
_______________________ test_solution[a=1\nb=2\nc=3\n-6] _______________________
challenges/2.2/test_solution.py:27: in test_solution
    assert received == expected_output
E   AssertionError: assert '' == 6
_____________________ test_solution[a=10\nb=11\nc=12\n-33] _____________________
challenges/2.2/test_solution.py:27: in test_solution
    assert received == expected_output
E   AssertionError: assert '' == 33
=========================== short test summary info ============================
FAILED challenges/2.2/test_solution.py::test_solution[a=1\nb=2\nc=3\n-6] - As...
FAILED challenges/2.2/test_solution.py::test_solution[a=10\nb=11\nc=12\n-33]
test_user,2.2,Test passed.. Error:
test_user,2.2,Test passed.. Error:
test_user,2.2,Test passed.. Error:
test_user,2.2,Test passed.. Error:
test_user,2.2,. Error:test failed: 
FF                                                                       [100%]
=================================== FAILURES ===================================
_______________________ test_solution[a=1\nb=2\nc=3\n-6] _______________________
challenges/2.2/test_solution.py:27: in test_solution
    assert received == expected_output
E   AssertionError: assert '' == 6
_____________________ test_solution[a=10\nb=11\nc=12\n-33] _____________________
challenges/2.2/test_solution.py:27: in test_solution
    assert received == expected_output
E   AssertionError: assert '' == 33
=========================== short test summary info ============================
FAILED challenges/2.2/test_solution.py::test_solution[a=1\nb=2\nc=3\n-6] - As...
FAILED challenges/2.2/test_solution.py::test_solution[a=10\nb=11\nc=12\n-33]
test_user,2.2,Test passed.. Error:
test_user,2.2,Test passed.. Error:
test_user,2.2,Test passed.. Error:
test_user,2.2,. Error:test failed: 
FF                                                                       [100%]
=================================== FAILURES ===================================
_______________________ test_solution[a=1\nb=2\nc=3\n-6] _______________________
challenges/2.2/test_solution.py:27: in test_solution
    assert received == expected_output
E   AssertionError: assert '' == 6
_____________________ test_solution[a=10\nb=11\nc=12\n-33] _____________________
challenges/2.2/test_solution.py:27: in test_solution
    assert received == expected_output
E   AssertionError: assert '' == 33
=========================== short test summary info ============================
FAILED challenges/2.2/test_solution.py::test_solution[a=1\nb=2\nc=3\n-6] - As...
FAILED challenges/2.2/test_solution.py::test_solution[a=10\nb=11\nc=12\n-33]
test_user,2.2,. Error:test failed: 
FF                                                                       [100%]
=================================== FAILURES ===================================
_______________________ test_solution[a=1\nb=2\nc=3\n-6] _______________________
challenges/2.2/test_solution.py:27: in test_solution
    assert received == expected_output
E   AssertionError: assert '' == 6
_____________________ test_solution[a=10\nb=11\nc=12\n-33] _____________________
challenges/2.2/test_solution.py:27: in test_solution
    assert received == expected_output
E   AssertionError: assert '' == 33
test_user,2.2,. Error:test failed: 
FF                                                                       [100%]
=================================== FAILURES ===================================
_______________________ test_solution[a=1\nb=2\nc=3\n-6] _______________________
challenges/2.2/test_solution.py:27: in test_solution
    assert received == expected_output
E   AssertionError: assert '6' == 6
_____________________ test_solution[a=10\nb=11\nc=12\n-33] _____________________
challenges/2.2/test_solution.py:27: in test_solution
    assert received == expected_output
E   AssertionError: assert '6' == 33
test_user,2.2,. Error:test failed: 
.F                                                                       [100%]
=================================== FAILURES ===================================
_____________________ test_solution[a=10\nb=11\nc=12\n-33] _____________________
challenges/2.2/test_solution.py:27: in test_solution
    assert received == expected_output
E   AssertionError: assert '6' == '33'
E     
E     - 33
E     + 6
test_user,2.2,. Error:test failed: 
FF                                                                       [100%]
=================================== FAILURES ===================================
_______________________ test_solution[a=1\nb=2\nc=3\n-6] _______________________
challenges/2.2/test_solution.py:23: in test_solution
    exec(code_to_test, globals=None, locals=None)
E   TypeError: 'globals' is an invalid keyword argument for exec()
_____________________ test_solution[a=10\nb=11\nc=12\n-33] _____________________
challenges/2.2/test_solution.py:23: in test_solution
    exec(code_to_test, globals=None, locals=None)
E   TypeError: 'globals' is an invalid keyword argument for exec()
test_user,2.2,. Error:test failed: 
.F                                                                       [100%]
=================================== FAILURES ===================================
_____________________ test_solution[a=10\nb=11\nc=12\n-33] _____________________
challenges/2.2/test_solution.py:27: in test_solution
    assert received_output == expected_output
E   AssertionError: assert '6' == '33'
E     
E     - 33
E     + 6
test_user,2.2,. Error:test failed: 
.F                                                                       [100%]
=================================== FAILURES ===================================
_____________________ test_solution[a=10\nb=11\nc=12\n-33] _____________________
challenges/2.2/test_solution.py:27: in test_solution
    assert received_output == expected_output
E   AssertionError: assert '6' == '33'
E     
E     - 33
E     + 6
test_user,2.2,. Error:test failed: 
.F                                                                       [100%]
=================================== FAILURES ===================================
_____________________ test_solution[a=10\nb=11\nc=12\n-33] _____________________
challenges/2.2/test_solution.py:27: in test_solution
    assert received_output == expected_output
E   AssertionError: assert '6' == '33'
E     
E     - 33
E     + 6
test_user,2.2,. Error:test failed: 
.F                                                                       [100%]
=================================== FAILURES ===================================
_____________________ test_solution[a=10\nb=11\nc=12\n-33] _____________________
challenges/2.2/test_solution.py:27: in test_solution
    assert received_output == expected_output
E   AssertionError: assert '6' == '33'
E     
E     - 33
E     + 6
test_user,2.2,. Error:test failed: 
== FAILURES ===================================
_____________________ test_solution[a=10\nb=11\nc=12\n-33] _____________________
challenges/2.2/test_solution.py:27: in test_solution
    assert received_output == expected_output
E   AssertionError: assert '6' == '33'
E     
E     - 33
E     + 6
test_user,2.2,. Error:test failed: 
did not execute
test_user,2.2,. Error:test failed: 
did not execute
test_user,2.2,. Error:test failed: 
.F                                                                       [100%]
=================================== FAILURES ===================================
_____________________ test_solution[a=10\nb=11\nc=12\n-33] _____________________
challenges/2.2/test_solution.py:27: in test_solution
    assert received_output == expected_output
E   AssertionError: assert '6' == '33'
E     
E     - 33
E     + 6
test_user,2.2,. Error:test failed: 
_____________________ test_solution[a=10\nb=11\nc=12\n-33] _____________________
challenges/2.2/test_solution.py:27: in test_solution
    assert received_output == expected_output
E   AssertionError: assert '6' == '33'
E     
E     - 33
E     + 6
test_user,2.2,. Error:TEST FAILED: 
_____________________ test_solution[a=10\nb=11\nc=12\n-33] _____________________
challenges/2.2/test_solution.py:27: in test_solution
    assert received_output == expected_output
E   AssertionError: assert '6' == '33'
E     
E     - 33
E     + 6
test_user,2.2,. Error:TEST FAILED: 
_____________________ test_solution[a=10\nb=11\nc=12\n-33] _____________________
challenges/2.2/test_solution.py:27: in test_solution
    assert received_output == expected_output
E   AssertionError: assert '6' == '33'
E     
E     - 33
E     + 6
test_user,2.2,. Error:TEST FAILED: 
_____________________ test_solution[
a=10
b=11
c=12
-33
] _____________________
challenges/2.2/test_solution.py:27: in test_solution
    assert received_output == expected_output
E   AssertionError: assert '6' == '33'
E     
E     - 33
E     + 6
test_user,2.2,. Error:TEST FAILED: 
_____________________ test_solution[
a=10
b=11
c=12
-33
] _____________________
challenges/2.2/test_solution.py:27: in test_solution
    assert received_output == expected_output
E   AssertionError: assert '6' == '33'
E     
E     - 33
E     + 6
test_user,2.2,. Error:TEST FAILED: 
_______________________ test_solution[
a=1
b=2
c=3
-6
] _______________________
challenges/2.2/test_solution.py:27: in test_solution
    assert received_output == expected_output
E   AssertionError: assert '8' == '6'
E     
E     - 6
E     + 8
_____________________ test_solution[
a=10
b=11
c=12
-33
] _____________________
challenges/2.2/test_solution.py:27: in test_solution
    assert received_output == expected_output
E   AssertionError: assert '8' == '33'
E     
E     - 33
E     + 8
test_user,2.2,. Error:TEST FAILED: 
_______________________ test_solution[
a=1
b=2
c=3
-6
] _______________________
challenges/2.2/test_solution.py:27: in test_solution
    assert received_output == expected_output
E   AssertionError: assert '8' == '6'
E     
E     - 6
E     + 8
_____________________ test_solution[
a=10
b=11
c=12
-33
] _____________________
challenges/2.2/test_solution.py:27: in test_solution
    assert received_output == expected_output
E   AssertionError: assert '8' == '33'
E     
E     - 33
E     + 8
test_user,2.2,. Error:TEST FAILED: 
_______________________ test_solution[
a=1
b=2
c=3
-6
] _______________________
challenges/2.2/test_solution.py:27: in test_solution
    assert received_output == expected_output
E   AssertionError: assert '8' == '6'
E     
E     - 6
E     + 8
___________________ test_solution[
a=10
b=11
c=12
-33
32
] ___________________
challenges/2.2/test_solution.py:27: in test_solution
    assert received_output == expected_output
E   AssertionError: assert '8' == '33\n32'
E     
E     + 8
E     - 33
E     - 32
test_user,2.2,. Error:TEST FAILED: 
_______________________ test_solution[
a=1
b=2
c=3
-6
] _______________________
challenges/2.2/test_solution.py:27: in test_solution
    assert received_output == expected_output
E   AssertionError: assert '8' == '6'
E     
E     - 6
E     + 8
___________________ test_solution[
a=10
b=11
c=12
-33
32
] ___________________
challenges/2.2/test_solution.py:27: in test_solution
    assert received_output == expected_output
E   AssertionError: assert '8' == '33\n32'
E     
E     + 8
E     - 33
E     - 32
test_user,2.2,. Error:TEST FAILED: 
_______________________ test_solution[
a=1
b=2
c=3
-6
] _______________________
challenges/2.2/test_solution.py:27: in test_solution
    assert received_output == expected_output
E   AssertionError: assert '8' == '6'
E     
E     - 6
E     + 8
___________________ test_solution[
a=10
b=11
c=12
-33
32
] ___________________
challenges/2.2/test_solution.py:27: in test_solution
    assert received_output == expected_output
E   AssertionError: assert '8' == '33\n32'
E     
E     + 8
E     - 33
E     - 32
test_user,2.2,. Error:TEST FAILED: 
_______________________ test_solution[
a=1
b=2
c=3
-6
] _______________________
challenges/2.2/test_solution.py:27: in test_solution
    assert received_output == expected_output
E   AssertionError: assert '8' == '6'
E     
E     - 6
E     + 8
__________________ test_solution[
a=10
b=11
c=12
-33
-32
] ___________________
challenges/2.2/test_solution.py:27: in test_solution
    assert received_output == expected_output
E   AssertionError: assert '8' == '33\n-32'
E     
E     + 8
E     - 33
E     - -32
test_user,2.2,. Error:TEST FAILED: 
==================================== ERRORS ====================================
_______________ ERROR collecting challenges/2.2/test_solution.py _______________
challenges/2.2/test_solution.py:10: in <lambda>
    ], ids=lambda params: f"Condition: {params[0]}, Expected: {params[1]}")
E   TypeError: 'int' object is not subscriptable

The above exception was the direct cause of the following exception:
/home/vscode/.local/lib/python3.11/site-packages/pluggy/_hooks.py:513: in __call__
    return self._hookexec(self.name, self._hookimpls.copy(), kwargs, firstresult)
/home/vscode/.local/lib/python3.11/site-packages/pluggy/_manager.py:120: in _hookexec
    return self._inner_hookexec(hook_name, methods, kwargs, firstresult)
/home/vscode/.local/lib/python3.11/site-packages/_pytest/python.py:248: in pytest_pycollect_makeitem
    return list(collector._genfunctions(name, obj))
/home/vscode/.local/lib/python3.11/site-packages/_pytest/python.py:461: in _genfunctions
    self.ihook.pytest_generate_tests.call_extra(methods, dict(metafunc=metafunc))
/home/vscode/.local/lib/python3.11/site-packages/pluggy/_hooks.py:574: in call_extra
    return self._hookexec(self.name, hookimpls, kwargs, firstresult)
/home/vscode/.local/lib/python3.11/site-packages/pluggy/_manager.py:120: in _hookexec
    return self._inner_hookexec(hook_name, methods, kwargs, firstresult)
/home/vscode/.local/lib/python3.11/site-packages/_pytest/python.py:118: in pytest_generate_tests
    metafunc.parametrize(*marker.args, **marker.kwargs, _param_mark=marker)
/home/vscode/.local/lib/python3.11/site-packages/_pytest/python.py:1239: in parametrize
    ids = self._resolve_parameter_set_ids(
/home/vscode/.local/lib/python3.11/site-packages/_pytest/python.py:1360: in _resolve_parameter_set_ids
    return id_maker.make_unique_parameterset_ids()
/home/vscode/.local/lib/python3.11/site-packages/_pytest/python.py:896: in make_unique_parameterset_ids
    resolved_ids = list(self._resolve_ids())
/home/vscode/.local/lib/python3.11/site-packages/_pytest/python.py:931: in _resolve_ids
    yield "-".join(
/home/vscode/.local/lib/python3.11/site-packages/_pytest/python.py:932: in <genexpr>
    self._idval(val, argname, idx)
/home/vscode/.local/lib/python3.11/site-packages/_pytest/python.py:938: in _idval
    idval = self._idval_from_function(val, argname, idx)
/home/vscode/.local/lib/python3.11/site-packages/_pytest/python.py:962: in _idval_from_function
    raise ValueError(msg) from e
E   ValueError: challenges/2.2/test_solution.py::test_solution: error raised while trying to determine id of parameter 'expected_output' at position 0
!!!!!!!!!!!!!!!!!!!! Interrupted: 1 error during collection !!!!!!!!!!!!!!!!!!!!
test_user,2.2,. Error:TEST FAILED: 
_ test_solution[Condition: a=1\nb=2\nc=3\n, Expected: a=1\nb=2\nc=3\n-Condition: 6, Expected: 6] _
challenges/2.2/test_solution.py:27: in test_solution
    assert received_output == expected_output
E   AssertionError: assert '8' == '6'
E     
E     - 6
E     + 8
_ test_solution[Condition: a=10\nb=11\nc=12\n, Expected: a=10\nb=11\nc=12\n-Condition: 33\n-32, Expected: 33\n-32] _
challenges/2.2/test_solution.py:27: in test_solution
    assert received_output == expected_output
E   AssertionError: assert '8' == '33\n-32'
E     
E     + 8
E     - 33
E     - -32
test_user,2.2,. Error:TEST FAILED: 
==================================== ERRORS ====================================
_______________ ERROR collecting challenges/2.2/test_solution.py _______________
challenges/2.2/test_solution.py:10: in <lambda>
    ], ids=lambda *params: f"Condition: {params[0]}, Expected: {params[1]}")
E   IndexError: tuple index out of range

The above exception was the direct cause of the following exception:
/home/vscode/.local/lib/python3.11/site-packages/pluggy/_hooks.py:513: in __call__
    return self._hookexec(self.name, self._hookimpls.copy(), kwargs, firstresult)
/home/vscode/.local/lib/python3.11/site-packages/pluggy/_manager.py:120: in _hookexec
    return self._inner_hookexec(hook_name, methods, kwargs, firstresult)
/home/vscode/.local/lib/python3.11/site-packages/_pytest/python.py:248: in pytest_pycollect_makeitem
    return list(collector._genfunctions(name, obj))
/home/vscode/.local/lib/python3.11/site-packages/_pytest/python.py:461: in _genfunctions
    self.ihook.pytest_generate_tests.call_extra(methods, dict(metafunc=metafunc))
/home/vscode/.local/lib/python3.11/site-packages/pluggy/_hooks.py:574: in call_extra
    return self._hookexec(self.name, hookimpls, kwargs, firstresult)
/home/vscode/.local/lib/python3.11/site-packages/pluggy/_manager.py:120: in _hookexec
    return self._inner_hookexec(hook_name, methods, kwargs, firstresult)
/home/vscode/.local/lib/python3.11/site-packages/_pytest/python.py:118: in pytest_generate_tests
    metafunc.parametrize(*marker.args, **marker.kwargs, _param_mark=marker)
/home/vscode/.local/lib/python3.11/site-packages/_pytest/python.py:1239: in parametrize
    ids = self._resolve_parameter_set_ids(
/home/vscode/.local/lib/python3.11/site-packages/_pytest/python.py:1360: in _resolve_parameter_set_ids
    return id_maker.make_unique_parameterset_ids()
/home/vscode/.local/lib/python3.11/site-packages/_pytest/python.py:896: in make_unique_parameterset_ids
    resolved_ids = list(self._resolve_ids())
/home/vscode/.local/lib/python3.11/site-packages/_pytest/python.py:931: in _resolve_ids
    yield "-".join(
/home/vscode/.local/lib/python3.11/site-packages/_pytest/python.py:932: in <genexpr>
    self._idval(val, argname, idx)
/home/vscode/.local/lib/python3.11/site-packages/_pytest/python.py:938: in _idval
    idval = self._idval_from_function(val, argname, idx)
/home/vscode/.local/lib/python3.11/site-packages/_pytest/python.py:962: in _idval_from_function
    raise ValueError(msg) from e
E   ValueError: challenges/2.2/test_solution.py::test_solution: error raised while trying to determine id of parameter 'start_condition' at position 0
!!!!!!!!!!!!!!!!!!!! Interrupted: 1 error during collection !!!!!!!!!!!!!!!!!!!!
test_user,2.2,. Error:TEST FAILED: 
____________ test_solution[
Condition: a=1
b=2
c=3
-Expected: 6
] _____________
challenges/2.2/test_solution.py:39: in test_solution
    assert received_output == expected_output
E   AssertionError: assert '8' == '6'
E     
E     - 6
E     + 8
________ test_solution[
Condition: a=10
b=11
c=12
-Expected: 33
-32
] ________
challenges/2.2/test_solution.py:39: in test_solution
    assert received_output == expected_output
E   AssertionError: assert '8' == '33\n-32'
E     
E     + 8
E     - 33
E     - -32
test_user,2.2,. Error:TEST FAILED: 
____________ test_solution[
Condition: a=1
b=2
c=3
-Expected: 6
] _____________
challenges/2.2/test_solution.py:48: in test_solution
    assert received_output == expected_output
E   AssertionError: assert '8' == '6'
E     
E     - 6
E     + 8
________ test_solution[
Condition: a=10
b=11
c=12
-Expected: 33
-32
] ________
challenges/2.2/test_solution.py:48: in test_solution
    assert received_output == expected_output
E   AssertionError: assert '8' == '33\n-32'
E     
E     + 8
E     - 33
E     - -32
test_user,2.2,. Error:TEST FAILED: 
____________ test_solution[
Condition: a=1
b=2
c=3
-Expected: 6
] _____________
challenges/2.2/test_solution.py:29: in test_solution
    assert received_output == expected_output
E   AssertionError: assert '8' == '6'
E     
E     - 6
E     + 8
________ test_solution[
Condition: a=10
b=11
c=12
-Expected: 33
-32
] ________
challenges/2.2/test_solution.py:29: in test_solution
    assert received_output == expected_output
E   AssertionError: assert '8' == '33\n-32'
E     
E     + 8
E     - 33
E     - -32
test_user,2.2,. Error:TEST FAILED: 
___________ test_solution[
Condition:
a=1
b=2
c=3
-Expected:
6
] ____________
challenges/2.2/test_solution.py:29: in test_solution
    assert received_output == expected_output
E   AssertionError: assert '8' == '6'
E     
E     - 6
E     + 8
_______ test_solution[
Condition:
a=10
b=11
c=12
-Expected:
33
-32
] _______
challenges/2.2/test_solution.py:29: in test_solution
    assert received_output == expected_output
E   AssertionError: assert '8' == '33\n-32'
E     
E     + 8
E     - 33
E     - -32
test_user,2.2,. Error:TEST FAILED: 
___________ test_solution[
Condition:
a=1
b=2
c=3
-Expected:
6
] ____________
challenges/2.2/test_solution.py:32: in test_solution
    starting_code = challenge_data.get("starting_code", '')
E   AttributeError: 'function' object has no attribute 'get'
_______ test_solution[
Condition:
a=10
b=11
c=12
-Expected:
33
-32
] _______
challenges/2.2/test_solution.py:32: in test_solution
    starting_code = challenge_data.get("starting_code", '')
E   AttributeError: 'function' object has no attribute 'get'
test_user,2.2,. Error:TEST FAILED: 
___________ test_solution[
Condition:
a=1
b=2
c=3
-Expected:
6
] ____________
challenges/2.2/test_solution.py:32: in test_solution
    starting_code = challenge_data.get("starting_code", '')
E   AttributeError: 'function' object has no attribute 'get'
_______ test_solution[
Condition:
a=10
b=11
c=12
-Expected:
33
-32
] _______
challenges/2.2/test_solution.py:32: in test_solution
    starting_code = challenge_data.get("starting_code", '')
E   AttributeError: 'function' object has no attribute 'get'
test_user,2.2,. Error:TEST FAILED: 
___________ test_solution[
Condition:
a=1
b=2
c=3
-Expected:
6
] ____________
challenges/2.2/test_solution.py:40: in test_solution
    starting_code = challenge_data.get("starting_code", '')
E   AttributeError: 'function' object has no attribute 'get'
_______ test_solution[
Condition:
a=10
b=11
c=12
-Expected:
33
-32
] _______
challenges/2.2/test_solution.py:40: in test_solution
    starting_code = challenge_data.get("starting_code", '')
E   AttributeError: 'function' object has no attribute 'get'
test_user,2.2,. Error:TEST FAILED: 
___________ test_solution[
Condition:
a=1
b=2
c=3
-Expected:
6
] ____________
challenges/2.2/test_solution.py:40: in test_solution
    starting_code = challenge_data.get("starting_code", '')
E   AttributeError: 'function' object has no attribute 'get'
_______ test_solution[
Condition:
a=10
b=11
c=12
-Expected:
33
-32
] _______
challenges/2.2/test_solution.py:40: in test_solution
    starting_code = challenge_data.get("starting_code", '')
E   AttributeError: 'function' object has no attribute 'get'
test_user,2.2,. Error:TEST FAILED: 
___________ test_solution[
Condition:
a=1
b=2
c=3
-Expected:
6
] ____________
challenges/2.2/test_solution.py:40: in test_solution
    starting_code = challenge_data.get("starting_code", '')
E   AttributeError: 'function' object has no attribute 'get'
_______ test_solution[
Condition:
a=10
b=11
c=12
-Expected:
33
-32
] _______
challenges/2.2/test_solution.py:40: in test_solution
    starting_code = challenge_data.get("starting_code", '')
E   AttributeError: 'function' object has no attribute 'get'
test_user,2.2,. Error:TEST FAILED: 
___________ test_solution[
Condition:
a=1
b=2
c=3
-Expected:
6
] ____________
challenges/2.2/test_solution.py:40: in test_solution
    starting_code = challenge_data.get("starting_code", '')
E   AttributeError: 'function' object has no attribute 'get'
----------------------------- Captured stdout call -----------------------------
challenge_data=<function challenge_data at 0x76dce2349e40>
_______ test_solution[
Condition:
a=10
b=11
c=12
-Expected:
33
-32
] _______
challenges/2.2/test_solution.py:40: in test_solution
    starting_code = challenge_data.get("starting_code", '')
E   AttributeError: 'function' object has no attribute 'get'
----------------------------- Captured stdout call -----------------------------
challenge_data=<function challenge_data at 0x76dce2349e40>
test_user,2.2,. Error:TEST FAILED: 
___________ test_solution[
Condition:
a=1
b=2
c=3
-Expected:
6
] ____________
challenges/2.2/test_solution.py:42: in test_solution
    code_to_test = code_submitted.replace(starting_code, start_condition)
E   AttributeError: 'function' object has no attribute 'replace'
----------------------------- Captured stdout call -----------------------------
challenge_data={'title': 'arithmatic operations', 'goal': 'understand how to combine arithmatic operations', 'description': 'With a, b, c print the result of:\nthe sum of a and b\n the product of b and c\n the c to the power of a', 'notes': 'The output should only calculation results, one result per line.', 'starting_code': '# ***Do not change this part***\na = 3\nb = 5\nc = 10\n# ***End of Do-not-change part***\n', 'expected_output': '8'}
_______ test_solution[
Condition:
a=10
b=11
c=12
-Expected:
33
-32
] _______
challenges/2.2/test_solution.py:42: in test_solution
    code_to_test = code_submitted.replace(starting_code, start_condition)
E   AttributeError: 'function' object has no attribute 'replace'
----------------------------- Captured stdout call -----------------------------
challenge_data={'title': 'arithmatic operations', 'goal': 'understand how to combine arithmatic operations', 'description': 'With a, b, c print the result of:\nthe sum of a and b\n the product of b and c\n the c to the power of a', 'notes': 'The output should only calculation results, one result per line.', 'starting_code': '# ***Do not change this part***\na = 3\nb = 5\nc = 10\n# ***End of Do-not-change part***\n', 'expected_output': '8'}
test_user,2.2,. Error:TEST FAILED: 
___________ test_solution[
Condition:
a=1
b=2
c=3
-Expected:
6
] ____________
challenges/2.2/test_solution.py:42: in test_solution
    code_to_test = code_submitted.replace(starting_code, start_condition)
E   AttributeError: 'function' object has no attribute 'replace'
_______ test_solution[
Condition:
a=10
b=11
c=12
-Expected:
33
-32
] _______
challenges/2.2/test_solution.py:42: in test_solution
    code_to_test = code_submitted.replace(starting_code, start_condition)
E   AttributeError: 'function' object has no attribute 'replace'
test_user,2.2,. Error:TEST FAILED: 
==================================== ERRORS ====================================
_______________ ERROR collecting challenges/2.2/test_solution.py _______________
/home/vscode/.local/lib/python3.11/site-packages/_pytest/python.py:492: in importtestmodule
    mod = import_path(
/home/vscode/.local/lib/python3.11/site-packages/_pytest/pathlib.py:591: in import_path
    importlib.import_module(module_name)
/usr/local/lib/python3.11/importlib/__init__.py:126: in import_module
    return _bootstrap._gcd_import(name[level:], package, level)
<frozen importlib._bootstrap>:1204: in _gcd_import
    ???
<frozen importlib._bootstrap>:1176: in _find_and_load
    ???
<frozen importlib._bootstrap>:1147: in _find_and_load_unlocked
    ???
<frozen importlib._bootstrap>:690: in _load_unlocked
    ???
/home/vscode/.local/lib/python3.11/site-packages/_pytest/assertion/rewrite.py:169: in exec_module
    source_stat, co = _rewrite_test(fn, self.config)
/home/vscode/.local/lib/python3.11/site-packages/_pytest/assertion/rewrite.py:349: in _rewrite_test
    tree = ast.parse(source, filename=strfn)
/usr/local/lib/python3.11/ast.py:50: in parse
    return compile(source, filename, mode, flags,
E     File "/workspaces/python-challenges/challenges/2.2/test_solution.py", line 32
E       def test_solution(challenge_data: dict, , code_submitted: str, start_condition: str, expected_output: str,
E                                               ^
E   SyntaxError: invalid syntax
!!!!!!!!!!!!!!!!!!!! Interrupted: 1 error during collection !!!!!!!!!!!!!!!!!!!!
test_user,2.2,. Error:TEST FAILED: 
___________ test_solution[
Condition:
a=1
b=2
c=3
-Expected:
6
] ____________
challenges/2.2/test_solution.py:47: in test_solution
    assert received_output == expected_output
E   AssertionError: assert '8' == '6'
E     
E     - 6
E     + 8
_______ test_solution[
Condition:
a=10
b=11
c=12
-Expected:
33
-32
] _______
challenges/2.2/test_solution.py:47: in test_solution
    assert received_output == expected_output
E   AssertionError: assert '8' == '33\n-32'
E     
E     + 8
E     - 33
E     - -32
test_user,2.2,. Error:TEST FAILED: 
___________ test_solution[
Condition:
a=1
b=2
c=3
-Expected:
6
] ____________
challenges/2.2/test_solution.py:53: in test_solution
    assert received_output == expected_output
E   AssertionError: assert '8' == '6'
E     
E     - 6
E     + 8
_______ test_solution[
Condition:
a=10
b=11
c=12
-Expected:
33
-32
] _______
challenges/2.2/test_solution.py:53: in test_solution
    assert received_output == expected_output
E   AssertionError: assert '8' == '33\n-32'
E     
E     + 8
E     - 33
E     - -32
test_user,2.2,. Error:TEST FAILED: 
_______ test_solution[
Condition:
a=10
b=11
c=12
-Expected:
33
-32
] _______
challenges/2.2/test_solution.py:53: in test_solution
    assert received_output == expected_output
E   AssertionError: assert '33' == '33\n-32'
E     
E     - 33
E     ?   -
E     + 33
E     - -32
test_user,2.2,. Error:TEST FAILED: 
_______ test_solution[
Condition:
a=10
b=11
c=12
-Expected:
33
-32
] _______
challenges/2.2/test_solution.py:53: in test_solution
    assert received_output == expected_output
E   AssertionError: assert '33' == '33\n-32'
E     
E     - 33
E     ?   -
E     + 33
E     - -32
test_user,2.2,. Error:TEST FAILED: 
___________ test_solution[
Condition:
a=1
b=2
c=3
-Expected:
6
] ____________
challenges/2.2/test_solution.py:53: in test_solution
    assert received_output == expected_output
E   AssertionError: assert '' == '6'
E     
E     - 6
_______ test_solution[
Condition:
a=10
b=11
c=12
-Expected:
33
-32
] _______
challenges/2.2/test_solution.py:53: in test_solution
    assert received_output == expected_output
E   AssertionError: assert '' == '33\n-32'
E     
E     - 33
E     - -32
test_user,2.2,. Error:TEST FAILED: 
___________ test_solution[
Condition:
a=1
b=2
c=3
-Expected:
6
] ____________
challenges/2.2/test_solution.py:53: in test_solution
    assert received_output == expected_output
E   AssertionError: assert '33\n-32' == '6'
E     
E     - 6
E     + 33
E     + -32
test_user,2.2,. Error:TEST FAILED: 
___________ test_solution[
Condition:
a=1
b=2
c=3
-Expected:
6
] ____________
challenges/2.2/test_solution.py:53: in test_solution
    assert received_output == expected_output
E   AssertionError: assert '12\n32\n12288\n6\n2\n6' == '6'
E     
E     + 12
E     + 32
E     + 12288
E     + 6
E     + 2
E       6
_______ test_solution[
Condition:
a=10
b=11
c=12
-Expected:
33
-32
] _______
challenges/2.2/test_solution.py:53: in test_solution
    assert received_output == expected_output
E   AssertionError: assert '12\n32\n12288\n6\n2\n6' == '33\n-32'
E     
E     - 33
E     - -32
E     + 12
E     + 32
E     + 12288
E     + 6
E     + 2
E     + 6
test_user,2.2,. Error:TEST FAILED: 
_ test_solution[Condition:\n# ***Do not change this part***\na = 3\nb = 5\nc = 4\n# ***End of Do-not-change part***\n-Expected:\n12\n32\n12288\n6\n2\n6] _
utils/generic_test.py:90: in test_solution
    assert received_output == expected_output
E   AssertionError: assert '16\n48\n207360\n20\n5\n2' == '12\n32\n12288\n6\n2\n6'
E     
E     - 12
E     - 32
E     - 12288
E     - 6
E     + 16
E     ? +...
E     
E     ...Full output truncated (8 lines hidden), use '-vv' to show
___ test_solution[
Condition:
a=2
b=1
c=3
-Expected:
6
9
54
4
1
0
] ____
utils/generic_test.py:90: in test_solution
    assert received_output == expected_output
E   AssertionError: assert '16\n48\n207360\n20\n5\n2' == '6\n9\n54\n4\n1\n0'
E     
E     - 6
E     + 16
E     ? +
E     - 9
E     - 54
E     - 4...
E     
E     ...Full output truncated (8 lines hidden), use '-vv' to show
__ test_solution[
Condition:
a=-1
b=0
c=1
-Expected:
0
-1
1
-2
-2
0
] __
utils/generic_test.py:90: in test_solution
    assert received_output == expected_output
E   AssertionError: assert '16\n48\n207360\n20\n5\n2' == '0\n-1\n1\n-2\n-2\n0'
E     
E     - 0
E     - -1
E     - 1
E     + 16
E     ?  +
E     - -2...
E     
E     ...Full output truncated (7 lines hidden), use '-vv' to show
test_user,2.2,. Error:TEST FAILED: 
_ test_solution[Condition:\na=10\nb=2c=4\n-Expected:\n16\n48\n207360\n20\n5\n2] _
utils/generic_test.py:84: in test_solution
    exec(code_to_test, None, None)
E     File "<string>", line 2
E       b=2c=4
E         ^
E   SyntaxError: invalid decimal literal
test_user,2.2,Test passed.. Error:
test_user,2.2,. Error:TEST FAILED: 
_ test_solution[Condition:\na=10\nb=2\nc=4\n-Expected:\n16\n48\n207360\n20\n5\n1] _
utils/generic_test.py:90: in test_solution
    assert received_output == expected_output
E   AssertionError: assert '16\n48\n207360\n20\n5\n2' == '16\n48\n207360\n20\n5\n1'
E     
E       16
E       48
E       207360
E       20
E       5
E     - 1
E     + 2
test_user,2.2,Test passed.. Error:
test_user,2.2,. Error:TEST FAILED: 
_ test_solution[
Condition:
a=10
b=2
c=4
-Expected:
16
48
207360
20
5
1
] _
utils/generic_test.py:90: in test_solution
    assert received_output == expected_output
E   AssertionError: assert '16\n48\n207360\n20\n5\n2' == '16\n48\n207360\n20\n5\n1'
E     
E       16
E       48
E       207360
E       20
E       5
E     - 1
E     + 2
test_user,2/1,Test passed.. Error:
test_user,2/1,. Error:TEST FAILED: 
_ test_solution[
Condition:
print(,)
print()
print()
print(,)-Expected:
3 3.14
(3+4j)
words b'bytes'
True False
None

] _
utils/generic_test.py:90: in test_solution
    assert received_output == expected_output
E   AssertionError: assert '3 3.14\n(3+4...mething wrong' == '3 3.14\n(3+4...False\nNone\n'
E     
E       3 3.14
E       (3+4j)
E       words b'bytes'
E       True False
E     - None
E     + something wrong
test_user,2/1,. Error:TEST FAILED: 
_ test_solution[
Condition:
print(,)
print()
print()
print(,)-Expected:
3 3.14
(3+4j)
words b'bytes'
True False
None

] _
utils/generic_test.py:90: in test_solution
    assert received_output == expected_output
E   AssertionError: assert '3 3.14\n(3+4...e False\nNone' == '3 3.14\n(3+4...False\nNone\n'
E     
E     Skipping 33 identical leading characters in diff, use -v to show
E        False
E     - None
E     ?     -
E     + None
test_user,2/1,. Error:TEST FAILED: 
_ test_solution[
Condition:
print(,)
print()
print()
print(,)-Expected:
3 3.14
(3+4j)
words b'bytes'
True False
None

] _
utils/generic_test.py:90: in test_solution
    assert received_output == expected_output
E   AssertionError: assert '3 3.14\n(3+4...e False\nNone' == '3 3.14\n(3+4...False\nNone\n'
E     
E     Skipping 33 identical leading characters in diff, use -v to show
E        False
E     - None
E     ?     -
E     + None
test_user,2/1,. Error:TEST FAILED: 
_ test_solution[
Condition:
print(,)
print()
print()
print(,)-Expected:
3 3.14
(3+4j)
words b'bytes'
True False
None

] _
utils/generic_test.py:90: in test_solution
    assert received_output == expected_output
E   AssertionError: assert '3 3.14\n(3+4...e False\nNone' == '3 3.14\n(3+4...False\nNone\n'
E     
E     Skipping 33 identical leading characters in diff, use -v to show
E        False
E     - None
E     ?     -
E     + None
test_user,2/1,Test passed.. Error:
test_user,2/1,Test passed.. Error:
test_user,2/1,. Error:TEST FAILED: 
did not execute
test_user,2/1,. Error:TEST FAILED: 
did not execute
test_user,2/1,Test passed.. Error:
test_user,2/1,Test passed.. Error:
test_user,2/1,. Error:TEST FAILED: 
Test returned Error 1:
_ test_solution[
Condition:
print(,)
print()
print(,)
print(,)-Expected:
3 3.14
(3+4j)
words b'bytes'
True False
None

] _
utils/generic_test.py:90: in test_solution
    assert received_output == expected_output
E   assert "3 3.14\n(3+4...'\nTrue False" == '3 3.14\n(3+4...e False\nNone'
E     
E       3 3.14
E       (3+4j)
E       words b'bytes'
E     - True False
E     ?           -
E     + True False
E     - None
test_user,2/1,Test passed.. Error:
test_user,2/1,Test passed.. Error:
test_user,2/1,. Error:TEST FAILED (rc=1):
_ test_solution[
Condition:
print(,)
print()
print(,)
print(,)-Expected:
3 3.14
(3+4j)
words b'bytes'
True False
None

] _
utils/generic_test.py:90: in test_solution
    assert received_output == expected_output
E   AssertionError: assert '3 3.14\n(3+4...se\nNone None' == '3 3.14\n(3+4...e False\nNone'
E     
E     Skipping 33 identical leading characters in diff, use -v to show
E        False
E     - None
E     + None None
test_user,2/1,. Error:TEST FAILED (rc=1):
_ test_solution[
Condition:
print(,)
print()
print(,)
print(,)
-Expected:
3 3.14
(3+4j)
words b'bytes'
True False
None

] _
utils/generic_test.py:90: in test_solution
    assert received_output == expected_output
E   AssertionError: assert '3 3.14\n(3+4...se\nNone None' == '3 3.14\n(3+4...e False\nNone'
E     
E     Skipping 33 identical leading characters in diff, use -v to show
E        False
E     - None
E     + None None
test_user,2/1,. Error:TEST FAILED (rc=1):
_ test_solution[
Condition:
print(,)
print()
print(,)
print(,)
-Expected:
3 3.14
(3+4j)
words b'bytes'
True False
None

] _
utils/generic_test.py:90: in test_solution
    assert received_output == expected_output
E   AssertionError: assert '3 3.14\n(3+4...se\nNone None' == '3 3.14\n(3+4...e False\nNone'
E     
E     Skipping 33 identical leading characters in diff, use -v to show
E        False
E     - None
E     + None None
test_user,2/1,. Error:TEST FAILED (rc=1):
_ test_solution[
Condition:
print(,)
print()
print(,)
print(,)
-Expected:
3 3.14
(3+4j)
words b'bytes'
True False
None

] _
utils/generic_test.py:90: in test_solution
    assert received_output == expected_output
E   AssertionError: assert '3 3.14\n(3+4...se\nNone None' == '3 3.14\n(3+4...e False\nNone'
E     
E     Skipping 33 identical leading characters in diff, use -v to show
E        False
E     - None
E     + None None
test_user,2/1,. Error:TEST FAILED (rc=1):
_ test_solution[
***Start Condition***:
print(,)
print()
print(,)
print(,)
-###Expected###:
3 3.14
(3+4j)
words b'bytes'
True False
None

] _
utils/generic_test.py:88: in test_solution
    assert received_output == expected_output
E   AssertionError: assert '3 3.14\n(3+4...se\nNone None' == '3 3.14\n(3+4...e False\nNone'
E     
E     Skipping 33 identical leading characters in diff, use -v to show
E        False
E     - None
E     + None None
test_user,2/1,Test passed.. Error:
test_user,2/2,Test passed.. Error:
test_user,2/2,. Error:TEST FAILED (rc=1):
________________________________ test_solution _________________________________
challenges/2/2/test_solution.py:14: in test_solution
    assert a == 42
E   NameError: name 'a' is not defined
test_user,2/2,. Error:TEST FAILED (rc=1):
________________________________ test_solution _________________________________
challenges/2/2/test_solution.py:14: in test_solution
    assert a == 42
E   NameError: name 'a' is not defined
test_user,2/2,Test passed.. Error:
test_user,2/1/1,. Error:TEST FAILED (rc=1):
_ test_solution[
***Start Condition***:
print(,)
print()
print(,)
print(,)
,print()
-###Expected###:
3 3.14
(3+4j)
words b'bytes'
True False
None

] _
utils/generic_test.py:88: in test_solution
    assert received_output == expected_output
E   AssertionError: assert '3 3.14' == '3 3.14\n(3+4...e False\nNone'
E     
E     - 3 3.14
E     ?       -
E     + 3 3.14
E     - (3+4j)
E     - words b'bytes'
E     - True False
E     - None
test_user,2/2,Test passed.. Error:
test_user,2/3/1III,. Error:TEST FAILED (rc=1):
________________________________ test_solution _________________________________
challenges/2/3/1III/test_solution.py:13: in test_solution
    exec(code_submitted)
E     File "<string>", line 13
E       answer_is_a_bool_type = 
E                               ^
E   SyntaxError: invalid syntax
test_user,2/3/1III,. Error:TEST FAILED (rc=1):
________________________________ test_solution _________________________________
challenges/2/3/1III/test_solution.py:17: in test_solution
    assert l['c'] == ''
E   AssertionError: assert '0' == ''
E     
E     + 0
test_user,2/3/1III,. Error:TEST FAILED (rc=1):
________________________________ test_solution _________________________________
challenges/2/3/1III/test_solution.py:29: in test_solution
    assert l['answer_is_g_Truthy'] is False
E   KeyError: 'answer_is_g_Truthy'
test_user,2/3/1III,Test passed.. Error:
test_user,2/3/1III,output=''. Error:error="TEST FAILED (rc=1):\n________________________________ test_solution _________________________________\nchallenges/2/3/1III/test_solution.py:15: in test_solution\n    assert l['a'] == 1\nE   assert 154 == 1\n----------------------------- Captured stdout call -----------------------------\n154 -155\n-56 -14\n159\n0\n105\n105\n525\n1365\n1365"
test_user,2/3/1III,output=''. Error:error="TEST FAILED (rc=1):\n_ test_solution[\n***Start Condition***:\n# given the below values of variable a to d, complete the following code: \n\n# print the value of a and bitwise NOT a:\nprint(,)\n\n# manually calculate bitwise NOT of b, and NOT c, and add answer to the \n#  right side of = of the following assignment statement (hint, for c, you \n#  actually don't need to do it bit by bit, although it is a perfectly \n#  legit way of doing it):\nanswer_bitwise_not_b = \nanswer_bitwise_not_c = \nprint(answer_bitwise_not_b, answer_bitwise_not_c)\n\n# consider a and c, with bitwise AND, XOR, OR, which operation of these\n#  two values will produce the largest amount, what is the result value of this\n#  operation? (use an expression to answer, but you need to know which\n#  operation produce the largest result):\nanswer_largest_bitwise_operation_of_a_and_c = \nprint(answer_largest_bitwise_operation_of_a_and_c)\n\n# The following code tries to multiply d by c using bitwise operations.\n# To simplify the solution, we will use add operation +, but we have\n# shown using bitwise operation to realize addition, so it's possible to\n# completely realize multiplication using bitwise operations only.\n# Your task is to complete the missing parts of the code below (note, we \n# intentionally break down the steps to step_0 to step_4, so we can check the\n# intermediate results and make sure you did everything correctly.  With 4 \n# steps, we will only be able to handle c<=15, that is ok for now.)\n\n# step0\nmultiplier = c\nresult = 0\nmultiplicand = d\nprint(result)\n\n# step1\nif multiplier & 1: \n    result += multiplicand\nmultiplicand = multiplicand << 1\nprint(result)\n\n# step2\nif multiplier & 2:\n    result += multiplicand\nmultiplicand <<= 1\nprint(result)\n\n# based on the above lines, use same logic, please finish ...step_3 \n# and ...ste_4, so that final result equals d * c\n# (please print intermediate result like above.)\n\n\n# final result\nprint(result)\n-###Expected###:\n154 -155\n200\n13\n0\n105\n105\n210\n315\n315\n315\n\n] _\nutils/generic_test.py:88: in test_solution\n    assert received_output == expected_output\nE   AssertionError: assert '154 -155\\n-5...5\\n1365\\n1365' == '154 -155\\n20...315\\n315\\n315'\nE     \nE       154 -155\nE     - 200\nE     - 13\nE     + -56 -14\nE     + 159\nE       0...\nE     \nE     ...Full output truncated (9 lines hidden), use '-vv' to show\n_ test_solution[\n***Start Condition***:\n-###Expected###:\n154 -155\n200\n13\n0\n105\n105\n210\n315\n315\n315\n154 -155\n200\n13\n0\n105\n105\n210\n315\n315\n315\n\n] _\nutils/generic_test.py:88: in test_solution\n    assert received_output == expected_output\nE   AssertionError: assert '154 -155\\n-5...5\\n1365\\n1365' == '154 -155\\n20...315\\n315\\n315'\nE     \nE       154 -155\nE     - 200\nE     - 13\nE     + -56 -14\nE     + 159\nE       0...\nE     \nE     ...Full output truncated (20 lines hidden), use '-vv' to show"
test_user,2/3/1III,output=''. Error:error="TEST FAILED (rc=1):\n_ test_solution[\n***Start Condition***:\na = 0b10011010\nb = 0b00110111\nc = 13\nd = 105\n-###Expected###:\n154 -155\n200\n13\n0\n105\n105\n210\n315\n315\n315\n\n] _\nutils/generic_test.py:88: in test_solution\n    assert received_output == expected_output\nE   AssertionError: assert '154 -155\\n-5...5\\n1365\\n1365' == '154 -155\\n20...315\\n315\\n315'\nE     \nE       154 -155\nE     - 200\nE     - 13\nE     + -56 -14\nE     + 159\nE       0...\nE     \nE     ...Full output truncated (9 lines hidden), use '-vv' to show\n_ test_solution[\n***Start Condition***:\n-###Expected###:\n154 -155\n200\n13\n0\n105\n105\n210\n315\n315\n315\n154 -155\n200\n13\n0\n105\n105\n210\n315\n315\n315\n\n] _\nutils/generic_test.py:82: in test_solution\n    exec(code_to_test, None, None)\n<string>:7: in <module>\n    ???\nE   NameError: name 'a' is not defined"
test_user,2/3/1III,output=''. Error:error="TEST FAILED (rc=1):\n_ test_solution[\n***Start Condition***:\na = 0b10011010\nb = 0b00110111\nc = 13\nd = 105\n-###Expected###:\n154 -155\n-56 -14\n159\n0\n105\n105\n210\n315\n315\n315\n\n] _\nutils/generic_test.py:88: in test_solution\n    assert received_output == expected_output\nE   AssertionError: assert '154 -155\\n-5...5\\n1365\\n1365' == '154 -155\\n-5...315\\n315\\n315'\nE     \nE       154 -155\nE       -56 -14\nE       159\nE       0\nE       105\nE       105...\nE     \nE     ...Full output truncated (7 lines hidden), use '-vv' to show\n_ test_solution[\n***Start Condition***:\n-###Expected###:\n154 -155\n-56 -14\n159\n0\n105\n105\n210\n315\n315\n315\n154 -155\n-56 -14\n159\n0\n105\n105\n210\n315\n315\n315\n\n] _\nutils/generic_test.py:82: in test_solution\n    exec(code_to_test, None, None)\n<string>:7: in <module>\n    ???\nE   NameError: name 'a' is not defined"
test_user,2/3/1III,output=''. Error:error="TEST FAILED (rc=1):\n_ test_solution[\n***Start Condition***:\na = 0b10011010\nb = 0b00110111\nc = 13\nd = 105\n-###Expected###:\n154 -155\n-56 -14\n159\n0\n105\n105\n210\n315\n315\n315\n\n] _\nutils/generic_test.py:88: in test_solution\n    assert received_output == expected_output\nE   AssertionError: assert '154 -155\\n-5...5\\n1365\\n1365' == '154 -155\\n-5...315\\n315\\n315'\nE     \nE       154 -155\nE       -56 -14\nE       159\nE       0\nE       105\nE       105...\nE     \nE     ...Full output truncated (7 lines hidden), use '-vv' to show"
test_user,2/3/1III,output=''. Error:error="TEST FAILED (rc=1):\n_ test_solution[\n***Start Condition***:\na = 0b10011010\nb = 0b00110111\nc = 13\nd = 105\n-###Expected###:\n154 -155\n-56 -14\n159\n0\n105\n105\n525\n1365\n1365\n\n] _\nutils/generic_test.py:88: in test_solution\n    assert received_output == expected_output\nE   AssertionError: assert '154 -155\\n-5...05\\n525\\n1365' == '154 -155\\n-5...5\\n1365\\n1365'\nE     \nE       154 -155\nE     - -56 -14\nE     ?      ^^\nE     + -56 -56\nE     ?      ^^\nE       159...\nE     \nE     ...Full output truncated (6 lines hidden), use '-vv' to show"
test_user,2/3/1III,output=''. Error:error="TEST FAILED (rc=1):\n_ test_solution[\n***Start Condition***:\na = 0b10011010\nb = 0b00110111\nc = 13\nd = 105\n-###Expected###:\n154 -155\n-56 -14\n159\n0\n105\n105\n525\n1365\n1365\n\n] _\nutils/generic_test.py:88: in test_solution\n    assert received_output == expected_output\nE   AssertionError: assert '154 -155\\n-5...05\\n525\\n1365' == '154 -155\\n-5...5\\n1365\\n1365'\nE     \nE       154 -155\nE       -56 -14\nE       159\nE       0\nE       105\nE       105...\nE     \nE     ...Full output truncated (3 lines hidden), use '-vv' to show"
test_user,2/3/1III,output=''. Error:error="TEST FAILED (rc=1):\n_ test_solution[\n***Start Condition***:\na = 0b10011010\nb = 0b00110111\nc = 13\nd = 105\n-###Expected###:\n154 -155\n-56 -14\n159\n0\n105\n105\n525\n1365\n1365\n\n] _\nutils/generic_test.py:88: in test_solution\n    assert received_output == expected_output\nE   AssertionError: assert '154 -155\\n-5...05\\n525\\n1365' == '154 -155\\n-5...5\\n1365\\n1365'\nE     \nE       154 -155\nE       -56 -14\nE       159\nE       0\nE       105\nE       105...\nE     \nE     ...Full output truncated (3 lines hidden), use '-vv' to show\n============================== 1 failed in 0.10s ==============================="
test_user,2/3/1III,output=''. Error:error="TEST FAILED (rc=1):\n_ test_solution[\n***Start Condition***:\na = 0b10011010\nb = 0b00110111\nc = 13\nd = 105\n-###Expected###:\n154 -155\n-56 -14\n159\n0\n105\n105\n525\n1365\n1365\n\n] _\nutils/generic_test.py:88: in test_solution\n    assert received_output == expected_output\nE   AssertionError: assert '154 -155\\n-5...05\\n525\\n1365' == '154 -155\\n-5...5\\n1365\\n1365'\nE     \nE       154 -155\nE       -56 -14\nE       159\nE       0\nE       105\nE       105...\nE     \nE     ...Full output truncated (3 lines hidden), use '-vv' to show\n============================== 1 failed in 0.09s ==============================="
test_user,2/3/1III,output=''. Error:error="TEST FAILED (rc=1):\n_ test_solution[\n***Start Condition***:\na = 0b10011010\nb = 0b00110111\nc = 13\nd = 105\n-###Expected###:\n154 -155\n-56 -14\n159\n0\n105\n105\n525\n1365\n1365\n\n] _\nutils/generic_test.py:88: in test_solution\n    assert received_output == expected_output\nE   AssertionError: assert '154 -155\\n-56 -14\\n159\\n0\\n105\\n105\\n525\\n1365' == '154 -155\\n-56 -14\\n159\\n0\\n105\\n105\\n525\\n1365\\n1365'\nE     \nE       154 -155\nE       -56 -14\nE       159\nE       0\nE       105\nE       105\nE       525\nE     - 1365\nE       1365\n============================== 1 failed in 0.09s ==============================="
test_user,2/3/1III,output='Test passed.'. Error:error=''
test_user,2/3/1III,output='Test passed.'. Error:error=''
test_user,2/3/1III,output=''. Error:error="TEST FAILED (rc=1):\n_ test_solution[\n***Start Condition***:\na = 24\nb = 83\nc = 11\nd = 72\n-###Expected###:\n154 -155\n-56 -14\n159\n0\n105\n105\n525\n1365\n24 -25\n-56 -14\n27\n0\n72\n216\n216\n792\n\n] _\nutils/generic_test.py:88: in test_solution\n    assert received_output == expected_output\nE   AssertionError: assert '24 -25\\n-84 -12\\n27\\n0\\n72\\n216\\n216\\n792' == '154 -155\\n-56 -14\\n159\\n0\\n105\\n105\\n525\\n1365\\n24 -25\\n-56 -14\\n27\\n0\\n72\\n216\\n216\\n792'\nE     \nE     - 154 -155\nE     - -56 -14\nE     - 159\nE     - 0\nE     - 105\nE     - 105\nE     - 525\nE     - 1365\nE       24 -25\nE     - -56 -14\nE     + -84 -12\nE       27\nE       0\nE       72\nE       216\nE       216\nE       792\n========================= 1 failed, 1 passed in 0.09s =========================="
test_user,2/3/1III,output=''. Error:error="TEST FAILED (rc=1):\n_ test_solution[\n***Start Condition***:\na = 24\nb = 83\nc = 11\nd = 72\n-###Expected###:\n24 -25\n-56 -14\n27\n0\n72\n216\n216\n792\n\n] _\nutils/generic_test.py:88: in test_solution\n    assert received_output == expected_output\nE   AssertionError: assert '24 -25\\n-84 -12\\n27\\n0\\n72\\n216\\n216\\n792' == '24 -25\\n-56 -14\\n27\\n0\\n72\\n216\\n216\\n792'\nE     \nE       24 -25\nE     - -56 -14\nE     + -84 -12\nE       27\nE       0\nE       72\nE       216\nE       216\nE       792\n========================= 1 failed, 1 passed in 0.10s =========================="
test_user,2/3/1III,output='Test passed.'. Error:error=''
test_user,5/7/5/1,output='Test passed.'. Error:error=''
test_user,5/7/5/1,output=''. Error:error='TEST FAILED (rc=1):\n_ test_solution[\n***Start Condition***:\n\n# number of teams that will be play playoff games\n# for now, we only handle no_of_playoff_teams = 2**n, which means all teams\n# have equal chances and same expected path to win (other number of playoff\n# teams will require some teams to skip certain rounds, which we won\'t worry\n# about for this challenge)\nno_of_playoff_teams = 8\n\n# Usually, out of all the playoff_teams, they will be ranked by points they\n# earned during group round robin games, and the highest ranked team will\n# play the lowest ranked team, the following is a simulation of the teams:\nplayoff_teams = [\nf"Team_{t}" for t in range(no_of_playoff_teams)\n]\n\ntime_field_availability = {\n    \'day_8_am\': [\n\'east\', \'west\', \'north\', \'south\'\n],\n    \'day_8_pm\': [\n\'east\', \'west\', \'north\', \'south\'\n],\n    \'day_9_am\': [\n\'east\', \'west\', \'north\', \'south\'\n],\n    \'day_9_pm\': [\n\'east\', \'west\', \'north\', \'south\'\n],\n}\n\n\n# function similate game report which team won their game\ndef winner_of(team_a: str, team_b: str) -> str:\n    #report game results, who won\n    game_played = True\n    if game_played:\n        return max(team_a, team_b)\n    else:\n        return f"winner between {team_a, team_b}"\n##### End do-not-change section #####\n-###Expected###:\n\n] _\nutils/generic_test.py:83: in test_solution\n    exec(code_to_test, None, None)\nE     File "<string>", line 77\nE       \tplayoff_match_schedule{"wrong":"incorrect"}\nE       ^\nE   TabError: inconsistent use of tabs and spaces in indentation\n============================== 1 failed in 0.12s ==============================='
test_user,5/7/5/1,output=''. Error:error='TEST FAILED (rc=1):\n_ test_solution[\n***Start Condition***:\n\n# number of teams that will be play playoff games\n# for now, we only handle no_of_playoff_teams = 2**n, which means all teams\n# have equal chances and same expected path to win (other number of playoff\n# teams will require some teams to skip certain rounds, which we won\'t worry\n# about for this challenge)\nno_of_playoff_teams = 8\n\n# Usually, out of all the playoff_teams, they will be ranked by points they\n# earned during group round robin games, and the highest ranked team will\n# play the lowest ranked team, the following is a simulation of the teams:\nplayoff_teams = [\nf"Team_{t}" for t in range(no_of_playoff_teams)\n]\n\ntime_field_availability = {\n    \'day_8_am\': [\n\'east\', \'west\', \'north\', \'south\'\n],\n    \'day_8_pm\': [\n\'east\', \'west\', \'north\', \'south\'\n],\n    \'day_9_am\': [\n\'east\', \'west\', \'north\', \'south\'\n],\n    \'day_9_pm\': [\n\'east\', \'west\', \'north\', \'south\'\n],\n}\n\n\n# function similate game report which team won their game\ndef winner_of(team_a: str, team_b: str) -> str:\n    #report game results, who won\n    game_played = True\n    if game_played:\n        return max(team_a, team_b)\n    else:\n        return f"winner between {team_a, team_b}"\n##### End do-not-change section #####\n-###Expected###:\n\n] _\nutils/generic_test.py:83: in test_solution\n    exec(code_to_test, None, None)\nE     File "<string>", line 77\nE       playoff_match_schedule{"wrong":"incorrect"}\nE                             ^\nE   SyntaxError: invalid syntax\n============================== 1 failed in 0.11s ==============================='
test_user,5/7/5/1,output='Test passed.'. Error:error=''
test_user,5/7/5/1,output='Test passed.'. Error:error=''
test_user,5/7/5/1,output=''. Error:error="TEST FAILED (rc=1):\n_____________________________ test_user_solutions ______________________________\nchallenges/5/7/5/1/test_solution.py:103: in test_user_solutions\n    assert schedule_playoff_matches(playoff_teams) == \\\nE   AssertionError: assert {((1, 8), '1/4'): ('day_8_pm', 'south'), ((2, 7), '1/4'): ('day_9_am', 'east'), ((3, 6), '1/4'): ('day_9_am', 'west'), ((4, 5), '1/4'): ('day_9_am', 'north'), ((1, 4), '1/2'): ('day_9_am', 'south'), ((2, 3), '1/2'): ('day_9_pm', 'east'), ((1, 2), '1/1'): ('day_9_pm', 'west')} == {((1, 8), '1/4'): ('day_8_pm', 'south'), ((2, 7), '1/4'): ('day_9_am', 'east'), ((3, 6), '1/4'): ('day_9_am', 'west'), ((4, 5), '1/4'): ('day_9_am', 'north'), ((1, 4), '1/2'): ('day_9_am', 'south'), ((2, 3), '1/2'): ('day_9_pm', 'east'), ((1, 2), '1/1'): ('day_9_pm', 'west'), 'wrong': 'incorrect'}\nE     \nE     Common items:\nE     {((1, 2), '1/1'): ('day_9_pm', 'west'),\nE      ((1, 4), '1/2'): ('day_9_am', 'south'),\nE      ((1, 8), '1/4'): ('day_8_pm', 'south'),\nE      ((2, 3), '1/2'): ('day_9_pm', 'east'),\nE      ((2, 7), '1/4'): ('day_9_am', 'east'),\nE      ((3, 6), '1/4'): ('day_9_am', 'west'),\nE      ((4, 5), '1/4'): ('day_9_am', 'north')}\nE     Right contains 1 more item:\nE     {'wrong': 'incorrect'}\nE     \nE     Full diff:\nE       {\nE     -     'wrong': 'incorrect',\nE           ((1, 2), '1/1'): (\nE               'day_9_pm',\nE               'west',\nE           ),\nE           ((1, 4), '1/2'): (\nE               'day_9_am',\nE               'south',\nE           ),\nE           ((1, 8), '1/4'): (\nE               'day_8_pm',\nE               'south',\nE           ),\nE           ((2, 3), '1/2'): (\nE               'day_9_pm',\nE               'east',\nE           ),\nE           ((2, 7), '1/4'): (\nE               'day_9_am',\nE               'east',\nE           ),\nE           ((3, 6), '1/4'): (\nE               'day_9_am',\nE               'west',\nE           ),\nE           ((4, 5), '1/4'): (\nE               'day_9_am',\nE               'north',\nE           ),\nE       }\n----------------------------- Captured stdout call -----------------------------\n('1/8', ['Team_0', 'Team_1', 'Team_2', 'Team_3', 'Team_4', 'Team_5', 'Team_6', 'Team_7'])\n('1/4', [(1, 8), (2, 7), (3, 6), (4, 5)])\n('1/2', [(1, 4), (2, 3)])\n('1/1', [(1, 2)])\n\nBy time and field:\n  0, ('day_8_am', 'east')\t 1/4\t(1, 8)\n  1, ('day_8_am', 'west')\t 1/4\t(2, 7)\n  2, ('day_8_am', 'north')\t 1/4\t(3, 6)\n  3, ('day_8_am', 'south')\t 1/4\t(4, 5)\n  4, ('day_8_pm', 'east')\t 1/2\t(1, 4)\n  5, ('day_8_pm', 'west')\t 1/2\t(2, 3)\n  6, ('day_8_pm', 'north')\t 1/1\t(1, 2)\n('1/8', ['Team_0', 'Team_1', 'Team_2', 'Team_3', 'Team_4', 'Team_5', 'Team_6', 'Team_7'])\n('1/4', [(1, 8), (2, 7), (3, 6), (4, 5)])\n('1/2', [(1, 4), (2, 3)])\n('1/1', [(1, 2)])\n\nBy time and field:\n  0, ('day_8_am', 'east')\t 1/4\t(1, 8)\n  1, ('day_8_am', 'west')\t 1/4\t(2, 7)\n  2, ('day_8_am', 'north')\t 1/4\t(3, 6)\n  3, ('day_8_am', 'south')\t 1/4\t(4, 5)\n  4, ('day_8_pm', 'east')\t 1/2\t(1, 4)\n  5, ('day_8_pm', 'west')\t 1/2\t(2, 3)\n  6, ('day_8_pm', 'north')\t 1/1\t(1, 2)\n('1/8', ['Team_0', 'Team_1', 'Team_2', 'Team_3', 'Team_4', 'Team_5', 'Team_6', 'Team_7'])\n('1/4', [(1, 8), (2, 7), (3, 6), (4, 5)])\n('1/2', [(1, 4), (2, 3)])\n('1/1', [(1, 2)])\n\nBy time and field:\n  0, ('day_8_pm', 'south')\t 1/4\t(1, 8)\n  1, ('day_9_am', 'east')\t 1/4\t(2, 7)\n  2, ('day_9_am', 'west')\t 1/4\t(3, 6)\n  3, ('day_9_am', 'north')\t 1/4\t(4, 5)\n  4, ('day_9_am', 'south')\t 1/2\t(1, 4)\n  5, ('day_9_pm', 'east')\t 1/2\t(2, 3)\n  6, ('day_9_pm', 'west')\t 1/1\t(1, 2)\n('1/8', ['Team_0', 'Team_1', 'Team_2', 'Team_3', 'Team_4', 'Team_5', 'Team_6', 'Team_7'])\n('1/4', [(1, 8), (2, 7), (3, 6), (4, 5)])\n('1/2', [(1, 4), (2, 3)])\n('1/1', [(1, 2)])\n\nBy time and field:\n  0, ('day_8_pm', 'south')\t 1/4\t(1, 8)\n  1, ('day_9_am', 'east')\t 1/4\t(2, 7)\n  2, ('day_9_am', 'west')\t 1/4\t(3, 6)\n  3, ('day_9_am', 'north')\t 1/4\t(4, 5)\n  4, ('day_9_am', 'south')\t 1/2\t(1, 4)\n  5, ('day_9_pm', 'east')\t 1/2\t(2, 3)\n  6, ('day_9_pm', 'west')\t 1/1\t(1, 2)\n----------------------------- Captured stderr call -----------------------------\n#    DEBUG - test_solution.py:101 test_solution.test_user_solutions() - user_module.schedule_playoff_matches(playoff_teams)={((1, 8), '1/4'): ('day_8_am', 'east'), ((2, 7), '1/4'): ('day_8_am', 'west'), ((3, 6), '1/4'): ('day_8_am', 'north'), ((4, 5), '1/4'): ('day_8_am', 'south'), ((1, 4), '1/2'): ('day_8_pm', 'east'), ((2, 3), '1/2'): ('day_8_pm', 'west'), ((1, 2), '1/1'): ('day_8_pm', 'north'), 'wrong': 'incorrect'}\n#    DEBUG - test_solution.py:102 test_solution.test_user_solutions() - schedule_playoff_matches(playoff_teams)={((1, 8), '1/4'): ('day_8_am', 'east'), ((2, 7), '1/4'): ('day_8_am', 'west'), ((3, 6), '1/4'): ('day_8_am', 'north'), ((4, 5), '1/4'): ('day_8_am', 'south'), ((1, 4), '1/2'): ('day_8_pm', 'east'), ((2, 3), '1/2'): ('day_8_pm', 'west'), ((1, 2), '1/1'): ('day_8_pm', 'north')}\n------------------------------ Captured log call -------------------------------\nDEBUG    test_solution:test_solution.py:101 user_module.schedule_playoff_matches(playoff_teams)={((1, 8), '1/4'): ('day_8_am', 'east'), ((2, 7), '1/4'): ('day_8_am', 'west'), ((3, 6), '1/4'): ('day_8_am', 'north'), ((4, 5), '1/4'): ('day_8_am', 'south'), ((1, 4), '1/2'): ('day_8_pm', 'east'), ((2, 3), '1/2'): ('day_8_pm', 'west'), ((1, 2), '1/1'): ('day_8_pm', 'north'), 'wrong': 'incorrect'}\nDEBUG    test_solution:test_solution.py:102 schedule_playoff_matches(playoff_teams)={((1, 8), '1/4'): ('day_8_am', 'east'), ((2, 7), '1/4'): ('day_8_am', 'west'), ((3, 6), '1/4'): ('day_8_am', 'north'), ((4, 5), '1/4'): ('day_8_am', 'south'), ((1, 4), '1/2'): ('day_8_pm', 'east'), ((2, 3), '1/2'): ('day_8_pm', 'west'), ((1, 2), '1/1'): ('day_8_pm', 'north')}\n============================== 1 failed in 0.14s ==============================="
test_user,5/7/5/1,output='Test passed.'. Error:error=''
test_user,5/7/5/1,output=''. Error:error="TEST FAILED (rc=1):\n_____________________________ test_user_solutions ______________________________\nchallenges/5/7/5/1/test_solution.py:103: in test_user_solutions\n    assert schedule_playoff_matches(playoff_teams) == \\\nE   AssertionError: assert {((1, 8), '1/4'): ('day_8_am', 'east'), ((2, 7), '1/4'): ('day_8_am', 'west'), ((3, 6), '1/4'): ('day_8_am', 'north'), ((4, 5), '1/4'): ('day_8_am', 'south'), ((1, 4), '1/2'): ('day_8_pm', 'east'), ((2, 3), '1/2'): ('day_8_pm', 'west'), ((1, 2), '1/1'): ('day_8_pm', 'north')} == {((1, 8), '1/4'): ('day_8_am', 'east'), ((2, 7), '1/4'): ('day_8_am', 'west'), ((3, 6), '1/4'): ('day_8_am', 'north'), ((4, 5), '1/4'): ('day_8_am', 'south'), ((1, 4), '1/2'): ('day_8_pm', 'east'), ((2, 3), '1/2'): ('day_8_pm', 'west'), ((1, 2), '1/1'): ('day_8_pm', 'north'), 'wrong': 'incorrect'}\nE     \nE     Common items:\nE     {((1, 2), '1/1'): ('day_8_pm', 'north'),\nE      ((1, 4), '1/2'): ('day_8_pm', 'east'),\nE      ((1, 8), '1/4'): ('day_8_am', 'east'),\nE      ((2, 3), '1/2'): ('day_8_pm', 'west'),\nE      ((2, 7), '1/4'): ('day_8_am', 'west'),\nE      ((3, 6), '1/4'): ('day_8_am', 'north'),\nE      ((4, 5), '1/4'): ('day_8_am', 'south')}\nE     Right contains 1 more item:\nE     {'wrong': 'incorrect'}\nE     \nE     Full diff:\nE       {\nE     -     'wrong': 'incorrect',\nE           ((1, 2), '1/1'): (\nE               'day_8_pm',\nE               'north',\nE           ),\nE           ((1, 4), '1/2'): (\nE               'day_8_pm',\nE               'east',\nE           ),\nE           ((1, 8), '1/4'): (\nE               'day_8_am',\nE               'east',\nE           ),\nE           ((2, 3), '1/2'): (\nE               'day_8_pm',\nE               'west',\nE           ),\nE           ((2, 7), '1/4'): (\nE               'day_8_am',\nE               'west',\nE           ),\nE           ((3, 6), '1/4'): (\nE               'day_8_am',\nE               'north',\nE           ),\nE           ((4, 5), '1/4'): (\nE               'day_8_am',\nE               'south',\nE           ),\nE       }\n----------------------------- Captured stdout call -----------------------------\n('1/8', ['Team_0', 'Team_1', 'Team_2', 'Team_3', 'Team_4', 'Team_5', 'Team_6', 'Team_7'])\n('1/4', [(1, 8), (2, 7), (3, 6), (4, 5)])\n('1/2', [(1, 4), (2, 3)])\n('1/1', [(1, 2)])\n\nBy time and field:\n  0, ('day_8_am', 'east')\t 1/4\t(1, 8)\n  1, ('day_8_am', 'west')\t 1/4\t(2, 7)\n  2, ('day_8_am', 'north')\t 1/4\t(3, 6)\n  3, ('day_8_am', 'south')\t 1/4\t(4, 5)\n  4, ('day_8_pm', 'east')\t 1/2\t(1, 4)\n  5, ('day_8_pm', 'west')\t 1/2\t(2, 3)\n  6, ('day_8_pm', 'north')\t 1/1\t(1, 2)\n('1/8', ['Team_0', 'Team_1', 'Team_2', 'Team_3', 'Team_4', 'Team_5', 'Team_6', 'Team_7'])\n('1/4', [(1, 8), (2, 7), (3, 6), (4, 5)])\n('1/2', [(1, 4), (2, 3)])\n('1/1', [(1, 2)])\n\nBy time and field:\n  0, ('day_8_am', 'east')\t 1/4\t(1, 8)\n  1, ('day_8_am', 'west')\t 1/4\t(2, 7)\n  2, ('day_8_am', 'north')\t 1/4\t(3, 6)\n  3, ('day_8_am', 'south')\t 1/4\t(4, 5)\n  4, ('day_8_pm', 'east')\t 1/2\t(1, 4)\n  5, ('day_8_pm', 'west')\t 1/2\t(2, 3)\n  6, ('day_8_pm', 'north')\t 1/1\t(1, 2)\n============================== 1 failed in 0.03s ==============================="
test_user,5/7/5/1,output=''. Error:error="TEST FAILED (rc=1):\n_____________________________ test_user_solutions ______________________________\nchallenges/5/7/5/1/test_solution.py:103: in test_user_solutions\n    assert schedule_playoff_matches(playoff_teams) == \\\nE   AssertionError: assert {((1, 8), '1/4'): ('day_8_am', 'east'), ((2, 7), '1/4'): ('day_8_am', 'west'), ((3, 6), '1/4'): ('day_8_am', 'north'), ((4, 5), '1/4'): ('day_8_am', 'south'), ((1, 4), '1/2'): ('day_8_pm', 'east'), ((2, 3), '1/2'): ('day_8_pm', 'west'), ((1, 2), '1/1'): ('day_8_pm', 'north')} == {((1, 8), '1/4'): ('day_8_am', 'east'), ((2, 7), '1/4'): ('day_8_am', 'west'), ((3, 6), '1/4'): ('day_8_am', 'north'), ((4, 5), '1/4'): ('day_8_am', 'south'), ((1, 4), '1/2'): ('day_8_pm', 'east'), ((2, 3), '1/2'): ('day_8_pm', 'west'), ((1, 2), '1/1'): ('day_8_pm', 'north'), 'wrong': 'incorrect'}\nE     \nE     Common items:\nE     {((1, 2), '1/1'): ('day_8_pm', 'north'),\nE      ((1, 4), '1/2'): ('day_8_pm', 'east'),\nE      ((1, 8), '1/4'): ('day_8_am', 'east'),\nE      ((2, 3), '1/2'): ('day_8_pm', 'west'),\nE      ((2, 7), '1/4'): ('day_8_am', 'west'),\nE      ((3, 6), '1/4'): ('day_8_am', 'north'),\nE      ((4, 5), '1/4'): ('day_8_am', 'south')}\nE     Right contains 1 more item:\nE     {'wrong': 'incorrect'}\nE     \nE     Full diff:\nE       {\nE     -     'wrong': 'incorrect',\nE           ((1, 2), '1/1'): (\nE               'day_8_pm',\nE               'north',\nE           ),\nE           ((1, 4), '1/2'): (\nE               'day_8_pm',\nE               'east',\nE           ),\nE           ((1, 8), '1/4'): (\nE               'day_8_am',\nE               'east',\nE           ),\nE           ((2, 3), '1/2'): (\nE               'day_8_pm',\nE               'west',\nE           ),\nE           ((2, 7), '1/4'): (\nE               'day_8_am',\nE               'west',\nE           ),\nE           ((3, 6), '1/4'): (\nE               'day_8_am',\nE               'north',\nE           ),\nE           ((4, 5), '1/4'): (\nE               'day_8_am',\nE               'south',\nE           ),\nE       }\n----------------------------- Captured stdout call -----------------------------\n('1/8', ['Team_0', 'Team_1', 'Team_2', 'Team_3', 'Team_4', 'Team_5', 'Team_6', 'Team_7'])\n('1/4', [(1, 8), (2, 7), (3, 6), (4, 5)])\n('1/2', [(1, 4), (2, 3)])\n('1/1', [(1, 2)])\n\nBy time and field:\n  0, ('day_8_am', 'east')\t 1/4\t(1, 8)\n  1, ('day_8_am', 'west')\t 1/4\t(2, 7)\n  2, ('day_8_am', 'north')\t 1/4\t(3, 6)\n  3, ('day_8_am', 'south')\t 1/4\t(4, 5)\n  4, ('day_8_pm', 'east')\t 1/2\t(1, 4)\n  5, ('day_8_pm', 'west')\t 1/2\t(2, 3)\n  6, ('day_8_pm', 'north')\t 1/1\t(1, 2)\n('1/8', ['Team_0', 'Team_1', 'Team_2', 'Team_3', 'Team_4', 'Team_5', 'Team_6', 'Team_7'])\n('1/4', [(1, 8), (2, 7), (3, 6), (4, 5)])\n('1/2', [(1, 4), (2, 3)])\n('1/1', [(1, 2)])\n\nBy time and field:\n  0, ('day_8_am', 'east')\t 1/4\t(1, 8)\n  1, ('day_8_am', 'west')\t 1/4\t(2, 7)\n  2, ('day_8_am', 'north')\t 1/4\t(3, 6)\n  3, ('day_8_am', 'south')\t 1/4\t(4, 5)\n  4, ('day_8_pm', 'east')\t 1/2\t(1, 4)\n  5, ('day_8_pm', 'west')\t 1/2\t(2, 3)\n  6, ('day_8_pm', 'north')\t 1/1\t(1, 2)\n============================== 1 failed in 0.03s ==============================="
test_user,5/7/5/1,output=''. Error:error='TEST FAILED (rc=2):============================= test session starts ==============================\nplatform linux -- Python 3.11.4, pytest-8.2.2, pluggy-1.5.0\nrootdir: /workspaces/python-challenges\nplugins: anyio-4.4.0\ncollected 1 item / 3 errors\n\n==================================== ERRORS ====================================\n_______________ ERROR collecting challenges/2/4/test_solution.py _______________\nimport file mismatch:\nimported module \'test_solution\' has this __file__ attribute:\n  /workspaces/python-challenges/challenges/2/2/test_solution.py\nwhich is not the same as the test file we want to collect:\n  /workspaces/python-challenges/challenges/2/4/test_solution.py\nHINT: remove __pycache__ / .pyc files and/or use a unique basename for your test file modules\n_____________ ERROR collecting challenges/5/7/5/1/test_solution.py _____________\nimport file mismatch:\nimported module \'test_solution\' has this __file__ attribute:\n  /workspaces/python-challenges/challenges/2/2/test_solution.py\nwhich is not the same as the test file we want to collect:\n  /workspaces/python-challenges/challenges/5/7/5/1/test_solution.py\nHINT: remove __pycache__ / .pyc files and/or use a unique basename for your test file modules\n____________________ ERROR collecting utils/generic_test.py ____________________\nutils/generic_test.py:60: in pytest_generate_tests\n    challenge_data = challenge_details(str(\nutils/common.py:7: in challenge_details\n    with open(f"{config.CHALLENGE_DIR}/{challenge_id}/{config.PROBLEM_FILENAME}",\nE   FileNotFoundError: [Errno 2] No such file or directory: \'challenges//problem.json\'\n=========================== short test summary info ============================\nERROR challenges/2/4/test_solution.py\nERROR challenges/5/7/5/1/test_solution.py\nERROR utils/generic_test.py - FileNotFoundError: [Errno 2] No such file or di...\n!!!!!!!!!!!!!!!!!!! Interrupted: 3 errors during collection !!!!!!!!!!!!!!!!!!!!\n============================== 3 errors in 0.34s ==============================='
test_user,5/7/5/1,output=''. Error:error='TEST FAILED (rc=2):============================= test session starts ==============================\nplatform linux -- Python 3.11.4, pytest-8.2.2, pluggy-1.5.0\nrootdir: /workspaces/python-challenges\nplugins: anyio-4.4.0\ncollected 1 item / 3 errors\n\n==================================== ERRORS ====================================\n_______________ ERROR collecting challenges/2/4/test_solution.py _______________\nimport file mismatch:\nimported module \'test_solution\' has this __file__ attribute:\n  /workspaces/python-challenges/challenges/2/2/test_solution.py\nwhich is not the same as the test file we want to collect:\n  /workspaces/python-challenges/challenges/2/4/test_solution.py\nHINT: remove __pycache__ / .pyc files and/or use a unique basename for your test file modules\n_____________ ERROR collecting challenges/5/7/5/1/test_solution.py _____________\nimport file mismatch:\nimported module \'test_solution\' has this __file__ attribute:\n  /workspaces/python-challenges/challenges/2/2/test_solution.py\nwhich is not the same as the test file we want to collect:\n  /workspaces/python-challenges/challenges/5/7/5/1/test_solution.py\nHINT: remove __pycache__ / .pyc files and/or use a unique basename for your test file modules\n____________________ ERROR collecting utils/generic_test.py ____________________\nutils/generic_test.py:60: in pytest_generate_tests\n    challenge_data = challenge_details(str(\nutils/common.py:7: in challenge_details\n    with open(f"{config.CHALLENGE_DIR}/{challenge_id}/{config.PROBLEM_FILENAME}",\nE   FileNotFoundError: [Errno 2] No such file or directory: \'challenges//problem.json\'\n=========================== short test summary info ============================\nERROR challenges/2/4/test_solution.py\nERROR challenges/5/7/5/1/test_solution.py\nERROR utils/generic_test.py - FileNotFoundError: [Errno 2] No such file or di...\n!!!!!!!!!!!!!!!!!!! Interrupted: 3 errors during collection !!!!!!!!!!!!!!!!!!!!\n============================== 3 errors in 0.32s ==============================='
test_user,5/7/5/1,output=''. Error:error='TEST FAILED (rc=2):============================= test session starts ==============================\nplatform linux -- Python 3.11.4, pytest-8.2.2, pluggy-1.5.0\nrootdir: /workspaces/python-challenges\nplugins: anyio-4.4.0\ncollected 1 item / 3 errors\n\n==================================== ERRORS ====================================\n_______________ ERROR collecting challenges/2/4/test_solution.py _______________\nimport file mismatch:\nimported module \'test_solution\' has this __file__ attribute:\n  /workspaces/python-challenges/challenges/2/2/test_solution.py\nwhich is not the same as the test file we want to collect:\n  /workspaces/python-challenges/challenges/2/4/test_solution.py\nHINT: remove __pycache__ / .pyc files and/or use a unique basename for your test file modules\n_____________ ERROR collecting challenges/5/7/5/1/test_solution.py _____________\nimport file mismatch:\nimported module \'test_solution\' has this __file__ attribute:\n  /workspaces/python-challenges/challenges/2/2/test_solution.py\nwhich is not the same as the test file we want to collect:\n  /workspaces/python-challenges/challenges/5/7/5/1/test_solution.py\nHINT: remove __pycache__ / .pyc files and/or use a unique basename for your test file modules\n____________________ ERROR collecting utils/generic_test.py ____________________\nutils/generic_test.py:60: in pytest_generate_tests\n    challenge_data = challenge_details(str(\nutils/common.py:7: in challenge_details\n    with open(f"{config.CHALLENGE_DIR}/{challenge_id}/{config.PROBLEM_FILENAME}",\nE   FileNotFoundError: [Errno 2] No such file or directory: \'challenges//problem.json\'\n=========================== short test summary info ============================\nERROR challenges/2/4/test_solution.py\nERROR challenges/5/7/5/1/test_solution.py\nERROR utils/generic_test.py - FileNotFoundError: [Errno 2] No such file or di...\n!!!!!!!!!!!!!!!!!!! Interrupted: 3 errors during collection !!!!!!!!!!!!!!!!!!!!\n============================== 3 errors in 0.38s ==============================='
test_user,5/7/5/1,output=''. Error:error="TEST FAILED (rc=1):\n_____________________________ test_user_solutions ______________________________\nchallenges/5/7/5/1/test_solution.py:103: in test_user_solutions\n    assert schedule_playoff_matches(playoff_teams) == \\\nE   AssertionError: assert {((1, 8), '1/4'): ('day_8_am', 'east'), ((2, 7), '1/4'): ('day_8_am', 'west'), ((3, 6), '1/4'): ('day_8_am', 'north'), ((4, 5), '1/4'): ('day_8_am', 'south'), ((1, 4), '1/2'): ('day_8_pm', 'east'), ((2, 3), '1/2'): ('day_8_pm', 'west'), ((1, 2), '1/1'): ('day_8_pm', 'north')} == {((1, 8), '1/4'): ('day_8_am', 'east'), ((2, 7), '1/4'): ('day_8_am', 'west'), ((3, 6), '1/4'): ('day_8_am', 'north'), ((4, 5), '1/4'): ('day_8_am', 'south'), ((1, 4), '1/2'): ('day_8_pm', 'east'), ((2, 3), '1/2'): ('day_8_pm', 'west'), ((1, 2), '1/1'): ('day_8_pm', 'north'), 'wrong': 'incorrect'}\nE     \nE     Common items:\nE     {((1, 2), '1/1'): ('day_8_pm', 'north'),\nE      ((1, 4), '1/2'): ('day_8_pm', 'east'),\nE      ((1, 8), '1/4'): ('day_8_am', 'east'),\nE      ((2, 3), '1/2'): ('day_8_pm', 'west'),\nE      ((2, 7), '1/4'): ('day_8_am', 'west'),\nE      ((3, 6), '1/4'): ('day_8_am', 'north'),\nE      ((4, 5), '1/4'): ('day_8_am', 'south')}\nE     Right contains 1 more item:\nE     {'wrong': 'incorrect'}\nE     \nE     Full diff:\nE       {\nE     -     'wrong': 'incorrect',\nE           ((1, 2), '1/1'): (\nE               'day_8_pm',\nE               'north',\nE           ),\nE           ((1, 4), '1/2'): (\nE               'day_8_pm',\nE               'east',\nE           ),\nE           ((1, 8), '1/4'): (\nE               'day_8_am',\nE               'east',\nE           ),\nE           ((2, 3), '1/2'): (\nE               'day_8_pm',\nE               'west',\nE           ),\nE           ((2, 7), '1/4'): (\nE               'day_8_am',\nE               'west',\nE           ),\nE           ((3, 6), '1/4'): (\nE               'day_8_am',\nE               'north',\nE           ),\nE           ((4, 5), '1/4'): (\nE               'day_8_am',\nE               'south',\nE           ),\nE       }\n----------------------------- Captured stdout call -----------------------------\n('1/8', ['Team_0', 'Team_1', 'Team_2', 'Team_3', 'Team_4', 'Team_5', 'Team_6', 'Team_7'])\n('1/4', [(1, 8), (2, 7), (3, 6), (4, 5)])\n('1/2', [(1, 4), (2, 3)])\n('1/1', [(1, 2)])\n\nBy time and field:\n  0, ('day_8_am', 'east')\t 1/4\t(1, 8)\n  1, ('day_8_am', 'west')\t 1/4\t(2, 7)\n  2, ('day_8_am', 'north')\t 1/4\t(3, 6)\n  3, ('day_8_am', 'south')\t 1/4\t(4, 5)\n  4, ('day_8_pm', 'east')\t 1/2\t(1, 4)\n  5, ('day_8_pm', 'west')\t 1/2\t(2, 3)\n  6, ('day_8_pm', 'north')\t 1/1\t(1, 2)\n('1/8', ['Team_0', 'Team_1', 'Team_2', 'Team_3', 'Team_4', 'Team_5', 'Team_6', 'Team_7'])\n('1/4', [(1, 8), (2, 7), (3, 6), (4, 5)])\n('1/2', [(1, 4), (2, 3)])\n('1/1', [(1, 2)])\n\nBy time and field:\n  0, ('day_8_am', 'east')\t 1/4\t(1, 8)\n  1, ('day_8_am', 'west')\t 1/4\t(2, 7)\n  2, ('day_8_am', 'north')\t 1/4\t(3, 6)\n  3, ('day_8_am', 'south')\t 1/4\t(4, 5)\n  4, ('day_8_pm', 'east')\t 1/2\t(1, 4)\n  5, ('day_8_pm', 'west')\t 1/2\t(2, 3)\n  6, ('day_8_pm', 'north')\t 1/1\t(1, 2)\n============================== 1 failed in 0.05s ==============================="
test_user,5/7/5/1,output='Test passed.'. Error:error=''
test_user,5/7/5/1,output='Test passed.'. Error:error=''
test_user,5/7/5/1,output=''. Error:error="TEST FAILED (rc=1):\n_____________________________ test_user_solutions ______________________________\nchallenges/5/7/5/1/test_solution.py:94: in test_user_solutions\n    assert schedule_playoff_matches(playoff_teams) == \\\nE   AssertionError: assert {((1, 2), '1/1'): ('day_8_pm', 'north'), ((1, 4), '1/2'): ('day_8_pm', 'east'), ((1, 8), '1/4'): ('day_8_am', 'east'), ((2, 3), '1/2'): ('day_8_pm', 'west'), ...} == None\nE    +  where {((1, 2), '1/1'): ('day_8_pm', 'north'), ((1, 4), '1/2'): ('day_8_pm', 'east'), ((1, 8), '1/4'): ('day_8_am', 'east'), ((2, 3), '1/2'): ('day_8_pm', 'west'), ...} = schedule_playoff_matches(['Team_0', 'Team_1', 'Team_2', 'Team_3', 'Team_4', 'Team_5', ...])\nE    +  and   None = <function schedule_playoff_matches at 0x7c0919d63ba0>(['Team_0', 'Team_1', 'Team_2', 'Team_3', 'Team_4', 'Team_5', ...])\nE    +    where <function schedule_playoff_matches at 0x7c0919d63ba0> = <module 'user_submissions.test_user.5.7.5.1' from '/workspaces/python-challenges/user_submissions/test_user/5/7/5/1.py'>.schedule_playoff_matches\n============================== 1 failed in 0.05s ==============================="
test_user,2/1/1,output=''. Error:error='TEST FAILED (rc=1):\n_ test_solution[\n***Start Condition***:\n-###Expected###:\n3 3.14\n(3+4j)\nwords b\'bytes\'\nTrue False\nNone\n\n] _\nutils/generic_test.py:83: in test_solution\n    exec(code_to_test, None, None)\nE     File "<string>", line 3\nE       print(,)\nE             ^\nE   SyntaxError: invalid syntax\n============================== 1 failed in 0.13s ==============================='
test_user,2/1/1,output='Test passed.'. Error:error=''
